<?xml version="1.0" ?>
<!-- =================================================================================== -->
<!-- |    This document was autogenerated by xacro from rb1_base_v3.urdf.xacro         | -->
<!-- |    EDITING THIS FILE BY HAND IS NOT RECOMMENDED                                 | -->
<!-- =================================================================================== -->
<robot name="rb1_base">
  <link name="base_footprint">
    <inertial>
      <mass value="1.0"/>
      <origin rpy="0 0 0" xyz="0 0 0"/>
      <inertia ixx="0.01" ixy="0.0" ixz="0.0" iyy="0.01" iyz="0.0" izz="0.01"/>
    </inertial>
    <visual>
      <origin rpy="0 0 0" xyz="0 0 0"/>
      <geometry>
        <box size="0.001 0.001 0.001"/>
      </geometry>
    </visual>
  </link>
  <joint name="base_footprint_joint" type="fixed">
    <origin rpy="0 0 0" xyz="0 0 0.25"/>
    <parent link="base_footprint"/>
    <child link="base_link"/>
  </joint>
  <!-- BASE_LINK -->
  <link name="base_link">
    <inertial>
      <mass value="25.0"/>
      <origin xyz="0 0 0"/>
      <inertia ixx="0.605" ixy="0.0" ixz="0.0" iyy="0.5435" iyz="0.0" izz="0.981"/>
    </inertial>
    <visual>
      <origin rpy="0 0 0" xyz="0 0 0"/>
      <geometry>
        <mesh filename="package://rb1_base_description/meshes/bases/rb1_base_v3.stl"/>
      </geometry>
      <material name="darkgrey">
        <color rgba="0.1 0.1 0.1 1"/>
      </material>
    </visual>
    <!--collision>
       <origin xyz="0 0 0" rpy="0 0 0 " />
       <geometry>
         <mesh filename="package://rb1_base_description/meshes/bases/rb1_base_v3.dae"/>
       </geometry>
    </collision-->
  </link>
  <joint name="front_cover_joint" type="fixed">
    <origin rpy="0 0 0 " xyz="0.220 0.0 0.004"/>
    <parent link="base_link"/>
    <child link="front_cover_link"/>
  </joint>
  <!-- FRONT COVER -->
  <link name="front_cover_link">
    <inertial>
      <mass value="0.25"/>
      <origin xyz="0 0 0"/>
      <inertia ixx="0.00007" ixy="0.0" ixz="0.0" iyy="0.00007" iyz="0.0" izz="0.0078"/>
    </inertial>
    <visual>
      <origin rpy="0 0 0" xyz="0 0 0"/>
      <geometry>
        <mesh filename="package://rb1_base_description/meshes/bases/rb1_front_cover_v3.stl"/>
      </geometry>
      <material name="black">
        <color rgba="0.0 0.0 0.0 1"/>
      </material>
    </visual>
    <collision>
      <origin rpy="0 0 0 " xyz="0 0 0"/>
      <geometry>
        <mesh filename="package://rb1_base_description/meshes/bases/rb1_front_cover_v3.dae"/>
      </geometry>
    </collision>
  </link>
  <joint name="top_covert_joint" type="fixed">
    <origin rpy="0 0 0 " xyz="0.0 0.0 0.243"/>
    <parent link="base_footprint"/>
    <child link="top_cover_link"/>
  </joint>
  <!-- FRONT COVER -->
  <link name="top_cover_link">
    <inertial>
      <mass value="0.25"/>
      <origin xyz="0 0 0"/>
      <inertia ixx="0.00007" ixy="0.0" ixz="0.0" iyy="0.00007" iyz="0.0" izz="0.0078"/>
    </inertial>
    <visual>
      <origin rpy="0 0 0" xyz="0 0 0"/>
      <geometry>
        <mesh filename="package://rb1_base_description/meshes/bases/rb1_top_cover_v3.stl"/>
      </geometry>
      <material name="black">
        <color rgba="0.0 0.0 0.0 1"/>
      </material>
    </visual>
    <collision>
      <origin rpy="0 0 0 " xyz="0 0 0"/>
      <geometry>
        <mesh filename="package://rb1_base_description/meshes/bases/rb1_top_cover_v3.dae"/>
      </geometry>
    </collision>
  </link>
  <!-- DOCKING CONTACTS -->
  <joint name="base_docking_joint" type="fixed">
    <origin rpy="0 0 0 " xyz="0.030 0.000 0.068"/>
    <parent link="front_cover_link"/>
    <child link="base_docking_contact_link"/>
  </joint>
  <!-- DOCKING LINK -->
  <link name="base_docking_contact_link">
    <inertial>
      <mass value="0.1"/>
      <origin rpy="0 0 0" xyz="0 0 0"/>
      <inertia ixx="0.001" ixy="0.0" ixz="0.0" iyy="0.001" iyz="0.0" izz="0.001"/>
    </inertial>
  </link>
  <!-- Aqui empieza el TORSOO-->
  <joint name="torso_joint" type="fixed">
    <parent link="base_footprint"/>
    <child link="torso_link"/>
    <origin rpy="0.0 0.0 0.0" xyz="-0.1 0.0 0.47"/>
    <axis rpy="0 0 0" xyz="0 0 1"/>
  </joint>
  <link name="torso_link">
    <visual>
      <origin rpy="0 0 0" xyz="0 0 0"/>
      <geometry>
        <mesh filename="package://rb1_base_description/meshes/others/rb1_torso_ur3.stl"/>
      </geometry>
    </visual>
    <collision>
      <origin rpy="0 0 0" xyz="0 0 0"/>
      <geometry>
        <mesh filename="package://rb1_base_description/meshes/others/rb1_torso_ur3.stl"/>
      </geometry>
    </collision>
    <inertial>
      <mass value="4.0"/>
      <origin xyz="0 0 0"/>
      <inertia ixx="0.1" ixy="0.0" ixz="0.0" iyy="0.1" iyz="0.0" izz="0.1"/>
    </inertial>
  </link>
  <joint name="torso_ur3_right_joint" type="fixed">
    <parent link="torso_link"/>
    <child link="torso_ur3_right_link"/>
    <origin rpy="0 -2.356194490192345 1.5707963267948966" xyz="0.17 -0.1655 0.954"/>
  </joint>
  <link name="torso_ur3_right_link">
  <inertial>
      <mass value="0.01"/>
      <origin xyz="0 0 0"/>
      <inertia ixx="0.1" ixy="0.0" ixz="0.0" iyy="0.1" iyz="0.0" izz="0.1"/>
    </inertial>
    </link>
  <joint name="torso_ur3_left_joint" type="fixed">
    <parent link="torso_link"/>
    <child link="torso_ur3_left_link"/>
    <origin rpy="0 -2.356194490192345 -1.5707963267948966" xyz="0.17 0.1655 0.954"/>
  </joint>
  <link name="torso_ur3_left_link">
  <inertial>
      <mass value="0.01"/>
      <origin xyz="0 0 0"/>
      <inertia ixx="0.1" ixy="0.0" ixz="0.0" iyy="0.1" iyz="0.0" izz="0.1"/>
    </inertial>
    </link>
    
    <!-- AQUI EMPIEZA EL BRAZO DERECHO -->
    <!-- measured from model -->
  <link name="right_arm_base_link">
    <visual>
      <origin rpy="0 0 3.141592653589793" xyz="0 0 0"/>
      <geometry>
        <mesh filename="package://ur_description/meshes/ur3/visual/base.dae"/>
      </geometry>
      <material name="LightGrey">
        <color rgba="0.7 0.7 0.7 1.0"/>
      </material>
    </visual>
    <collision>
      <origin rpy="0 0 3.141592653589793" xyz="0 0 0"/>
      <geometry>
        <mesh filename="package://ur_description/meshes/ur3/collision/base.stl"/>
      </geometry>
    </collision>
    <inertial>
      <mass value="2.0"/>
      <origin rpy="0 0 0" xyz="0.0 0.0 0.0"/>
      <inertia ixx="0.0030531654454" ixy="0.0" ixz="0.0" iyy="0.0030531654454" iyz="0.0" izz="0.005625"/>
    </inertial>
  </link>
  <joint name="right_arm_shoulder_pan_joint" type="revolute">
    <parent link="right_arm_base_link"/>
    <child link="right_arm_shoulder_link"/>
    <origin rpy="0 0 3.141592653589793" xyz="0 0 0.1519"/>
    <axis xyz="0 0 1"/>
    <limit effort="330.0" lower="-3.141592653589793" upper="3.141592653589793" velocity="2.16"/>
    <dynamics damping="0.0" friction="0.0"/>
  </joint>
  <link name="right_arm_shoulder_link">
    <visual>
      <origin rpy="0 0 3.141592653589793" xyz="0 0 0"/>
      <geometry>
        <mesh filename="package://ur_description/meshes/ur3/visual/shoulder.dae"/>
      </geometry>
      <material name="LightGrey">
        <color rgba="0.7 0.7 0.7 1.0"/>
      </material>
    </visual>
    <collision>
      <origin rpy="0 0 3.141592653589793" xyz="0 0 0"/>
      <geometry>
        <mesh filename="package://ur_description/meshes/ur3/collision/shoulder.stl"/>
      </geometry>
    </collision>
    <inertial>
      <mass value="2.0"/>
      <origin rpy="0 0 0" xyz="0.0 0.0 0.0"/>
      <inertia ixx="0.008093163429399999" ixy="0.0" ixz="0.0" iyy="0.008093163429399999" iyz="0.0" izz="0.005625"/>
    </inertial>
  </link>
  <joint name="right_arm_shoulder_lift_joint" type="revolute">
    <parent link="right_arm_shoulder_link"/>
    <child link="right_arm_upper_arm_link"/>
    <origin rpy="1.570796327 0 0" xyz="0 0 0"/>
    <axis xyz="0 0 1"/>
    <limit effort="330.0" lower="-3.141592653589793" upper="3.141592653589793" velocity="2.16"/>
    <dynamics damping="0.0" friction="0.0"/>
  </joint>
  <link name="right_arm_upper_arm_link">
    <visual>
      <origin rpy="1.5707963267948966 0 -1.5707963267948966" xyz="0 0 0.1198"/>
      <geometry>
        <mesh filename="package://ur_description/meshes/ur3/visual/upperarm.dae"/>
      </geometry>
      <material name="LightGrey">
        <color rgba="0.7 0.7 0.7 1.0"/>
      </material>
    </visual>
    <collision>
      <origin rpy="1.5707963267948966 0 -1.5707963267948966" xyz="0 0 0.1198"/>
      <geometry>
        <mesh filename="package://ur_description/meshes/ur3/collision/upperarm.stl"/>
      </geometry>
    </collision>
    <inertial>
      <mass value="3.42"/>
      <origin rpy="0 1.5707963267948966 0" xyz="-0.121825 0.0 0.12"/>
      <inertia ixx="0.021728483221103233" ixy="0.0" ixz="0.0" iyy="0.021728483221103233" iyz="0.0" izz="0.00961875"/>
    </inertial>
  </link>
  <joint name="right_arm_elbow_joint" type="revolute">
    <parent link="right_arm_upper_arm_link"/>
    <child link="right_arm_forearm_link"/>
    <origin rpy="0 0 0" xyz="-0.24365 0 0"/>
    <axis xyz="0 0 1"/>
    <limit effort="150.0" lower="-3.141592653589793" upper="3.141592653589793" velocity="3.15"/>
    <dynamics damping="0.0" friction="0.0"/>
  </joint>
  <link name="right_arm_forearm_link">
    <visual>
      <origin rpy="1.5707963267948966 0 -1.5707963267948966" xyz="0 0 0.0275"/>
      <geometry>
        <mesh filename="package://ur_description/meshes/ur3/visual/forearm.dae"/>
      </geometry>
      <material name="LightGrey">
        <color rgba="0.7 0.7 0.7 1.0"/>
      </material>
    </visual>
    <collision>
      <origin rpy="1.5707963267948966 0 -1.5707963267948966" xyz="0 0 0.0275"/>
      <geometry>
        <mesh filename="package://ur_description/meshes/ur3/collision/forearm.stl"/>
      </geometry>
    </collision>
    <inertial>
      <mass value="1.26"/>
      <origin rpy="0 1.5707963267948966 0" xyz="-0.121825 0.0 0.0275"/>
      <inertia ixx="0.006546806443776375" ixy="0.0" ixz="0.0" iyy="0.006546806443776375" iyz="0.0" izz="0.00354375"/>
    </inertial>
  </link>
  <joint name="right_arm_wrist_1_joint" type="revolute">
    <parent link="right_arm_forearm_link"/>
    <child link="right_arm_wrist_1_link"/>
    <origin rpy="0 0 0" xyz="-0.21325 0 0.11235"/>
    <axis xyz="0 0 1"/>
    <limit effort="54.0" lower="-3.141592653589793" upper="3.141592653589793" velocity="3.2"/>
    <dynamics damping="0.0" friction="0.0"/>
  </joint>
  <link name="right_arm_wrist_1_link">
    <visual>
      <origin rpy="1.5707963267948966 0 0" xyz="0 0 -0.085"/>
      <geometry>
        <mesh filename="package://ur_description/meshes/ur3/visual/wrist1.dae"/>
      </geometry>
      <material name="LightGrey">
        <color rgba="0.7 0.7 0.7 1.0"/>
      </material>
    </visual>
    <collision>
      <origin rpy="1.5707963267948966 0 0" xyz="0 0 -0.085"/>
      <geometry>
        <mesh filename="package://ur_description/meshes/ur3/collision/wrist1.stl"/>
      </geometry>
    </collision>
    <inertial>
      <mass value="0.8"/>
      <origin rpy="0 0 0" xyz="0.0 0.0 0.0"/>
      <inertia ixx="0.0016106408557434" ixy="0.0" ixz="0.0" iyy="0.0016106408557434" iyz="0.0" izz="0.00225"/>
    </inertial>
  </link>
  <joint name="right_arm_wrist_2_joint" type="revolute">
    <parent link="right_arm_wrist_1_link"/>
    <child link="right_arm_wrist_2_link"/>
    <origin rpy="1.570796327 0 0" xyz="0 -0.08535 -1.750557762378351e-11"/>
    <axis xyz="0 0 1"/>
    <limit effort="54.0" lower="-3.141592653589793" upper="3.141592653589793" velocity="3.2"/>
    <dynamics damping="0.0" friction="0.0"/>
  </joint>
  <link name="right_arm_wrist_2_link">
    <visual>
      <origin rpy="0 0 0" xyz="0 0 -0.085"/>
      <geometry>
        <mesh filename="package://ur_description/meshes/ur3/visual/wrist2.dae"/>
      </geometry>
      <material name="LightGrey">
        <color rgba="0.7 0.7 0.7 1.0"/>
      </material>
    </visual>
    <collision>
      <origin rpy="0 0 0" xyz="0 0 -0.085"/>
      <geometry>
        <mesh filename="package://ur_description/meshes/ur3/collision/wrist2.stl"/>
      </geometry>
    </collision>
    <inertial>
      <mass value="0.8"/>
      <origin rpy="0 0 0" xyz="0.0 0.0 0.0"/>
      <inertia ixx="0.0015721733711303997" ixy="0.0" ixz="0.0" iyy="0.0015721733711303997" iyz="0.0" izz="0.00225"/>
    </inertial>
  </link>
  <joint name="right_arm_wrist_3_joint" type="revolute">
    <parent link="right_arm_wrist_2_link"/>
    <child link="right_arm_wrist_3_link"/>
    <origin rpy="1.570796326589793 3.141592653589793 3.141592653589793" xyz="0 0.0819 -1.679797079540562e-11"/>
    <axis xyz="0 0 1"/>
    <limit effort="54.0" lower="-3.141592653589793" upper="3.141592653589793" velocity="3.2"/>
    <dynamics damping="0.0" friction="0.0"/>
  </joint>
  <link name="right_arm_wrist_3_link">
    <visual>
      <origin rpy="1.5707963267948966 0 0" xyz="0 0 -0.082"/>
      <geometry>
        <mesh filename="package://ur_description/meshes/ur3/visual/wrist3.dae"/>
      </geometry>
      <material name="LightGrey">
        <color rgba="0.7 0.7 0.7 1.0"/>
      </material>
    </visual>
    <collision>
      <origin rpy="1.5707963267948966 0 0" xyz="0 0 -0.082"/>
      <geometry>
        <mesh filename="package://ur_description/meshes/ur3/collision/wrist3.stl"/>
      </geometry>
    </collision>
    <inertial>
      <mass value="0.35"/>
      <origin rpy="0 0 0" xyz="0.0 0.0 -0.01525"/>
      <inertia ixx="0.00020431970993874997" ixy="0.0" ixz="0.0" iyy="0.00020431970993874997" iyz="0.0" izz="0.000354375"/>
    </inertial>
  </link>
  <joint name="right_arm_ee_fixed_joint" type="fixed">
    <parent link="right_arm_wrist_3_link"/>
    <child link="right_arm_ee_link"/>
    <origin rpy="0.0 -1.5707963267948966 1.5707963267948966" xyz="0.0 0.0 0.0"/>
  </joint>
  <link name="right_arm_ee_link">
    <collision>
      <geometry>
        <box size="0.01 0.01 0.01"/>
      </geometry>
      <origin rpy="0 0 0" xyz="-0.01 0 0"/>
    </collision>
  </link>
  <joint name="right_arm_wrist_3_passive_joint" type="fixed">
    <origin rpy="0 0 0" xyz="0 0 0"/>
    <parent link="right_arm_wrist_3_link"/>
    <child link="right_arm_tool0"/>
  </joint>
  <transmission name="right_arm_shoulder_pan_trans">
    <type>transmission_interface/SimpleTransmission</type>
    <joint name="right_arm_shoulder_pan_joint">
      <hardwareInterface>hardware_interface/PositionJointInterface</hardwareInterface>
    </joint>
    <actuator name="right_arm_shoulder_pan_motor">
      <mechanicalReduction>1</mechanicalReduction>
    </actuator>
  </transmission>
  <transmission name="right_arm_shoulder_lift_trans">
    <type>transmission_interface/SimpleTransmission</type>
    <joint name="right_arm_shoulder_lift_joint">
      <hardwareInterface>hardware_interface/PositionJointInterface</hardwareInterface>
    </joint>
    <actuator name="right_arm_shoulder_lift_motor">
      <mechanicalReduction>1</mechanicalReduction>
    </actuator>
  </transmission>
  <transmission name="right_arm_elbow_trans">
    <type>transmission_interface/SimpleTransmission</type>
    <joint name="right_arm_elbow_joint">
      <hardwareInterface>hardware_interface/PositionJointInterface</hardwareInterface>
    </joint>
    <actuator name="right_arm_elbow_motor">
      <mechanicalReduction>1</mechanicalReduction>
    </actuator>
  </transmission>
  <transmission name="right_arm_wrist_1_trans">
    <type>transmission_interface/SimpleTransmission</type>
    <joint name="right_arm_wrist_1_joint">
      <hardwareInterface>hardware_interface/PositionJointInterface</hardwareInterface>
    </joint>
    <actuator name="right_arm_wrist_1_motor">
      <mechanicalReduction>1</mechanicalReduction>
    </actuator>
  </transmission>
  <transmission name="right_arm_wrist_2_trans">
    <type>transmission_interface/SimpleTransmission</type>
    <joint name="right_arm_wrist_2_joint">
      <hardwareInterface>hardware_interface/PositionJointInterface</hardwareInterface>
    </joint>
    <actuator name="right_arm_wrist_2_motor">
      <mechanicalReduction>1</mechanicalReduction>
    </actuator>
  </transmission>
  <transmission name="right_arm_wrist_3_trans">
    <type>transmission_interface/SimpleTransmission</type>
    <joint name="right_arm_wrist_3_joint">
      <hardwareInterface>hardware_interface/PositionJointInterface</hardwareInterface>
    </joint>
    <actuator name="right_arm_wrist_3_motor">
      <mechanicalReduction>1</mechanicalReduction>
    </actuator>
  </transmission>
  <gazebo reference="right_arm_shoulder_link">
    <selfCollide>true</selfCollide>
  </gazebo>
  <gazebo reference="right_arm_upper_arm_link">
    <selfCollide>true</selfCollide>
  </gazebo>
  <gazebo reference="right_arm_forearm_link">
    <selfCollide>true</selfCollide>
  </gazebo>
  <gazebo reference="right_arm_wrist_1_link">
    <selfCollide>true</selfCollide>
  </gazebo>
  <gazebo reference="right_arm_wrist_3_link">
    <selfCollide>true</selfCollide>
  </gazebo>
  <gazebo reference="right_arm_wrist_2_link">
    <selfCollide>true</selfCollide>
  </gazebo>
  <gazebo reference="right_arm_ee_link">
    <selfCollide>true</selfCollide>
  </gazebo>
  <!-- ROS base_link to UR 'Base' Coordinates transform -->
  <!--link name="right_arm_base"/-->
  <!--joint name="right_arm_base_link-base_fixed_joint" type="fixed">
    <origin rpy="0 0 -3.141592653589793" xyz="0 0 0"/>
    <parent link="right_arm_base_link"/>
    <child link="right_arm_base"/>
  </joint-->
  <!-- Frame coincident with all-zeros TCP on UR controller -->
  <link name="right_arm_tool0"/>
  
  <!-- JOINT DEL BRAZO DERECHO CON EL ROBOT -->
  <joint name="$right_arm_base_joint" type="fixed">
	<origin xyz="0.0 0.0 0.0" rpy="0.0 0.0 0.0"/>
	<parent link="torso_ur3_right_link" />
	<child link="right_arm_base_link" />
</joint>
<!-- BRAZO IZQUEIRDO DEL ROBOT -->
<!-- measured from model -->
  <link name="left_arm_base_link">
    <visual>
      <origin rpy="0 0 3.141592653589793" xyz="0 0 0"/>
      <geometry>
        <mesh filename="package://ur_description/meshes/ur3/visual/base.dae"/>
      </geometry>
      <material name="LightGrey">
        <color rgba="0.7 0.7 0.7 1.0"/>
      </material>
    </visual>
    <collision>
      <origin rpy="0 0 3.141592653589793" xyz="0 0 0"/>
      <geometry>
        <mesh filename="package://ur_description/meshes/ur3/collision/base.stl"/>
      </geometry>
    </collision>
    <inertial>
      <mass value="2.0"/>
      <origin rpy="0 0 0" xyz="0.0 0.0 0.0"/>
      <inertia ixx="0.0030531654454" ixy="0.0" ixz="0.0" iyy="0.0030531654454" iyz="0.0" izz="0.005625"/>
    </inertial>
  </link>
  <joint name="left_arm_shoulder_pan_joint" type="revolute">
    <parent link="left_arm_base_link"/>
    <child link="left_arm_shoulder_link"/>
    <origin rpy="0 0 3.141592653589793" xyz="0 0 0.1519"/>
    <axis xyz="0 0 1"/>
    <limit effort="330.0" lower="-3.141592653589793" upper="3.141592653589793" velocity="2.16"/>
    <dynamics damping="0.0" friction="0.0"/>
  </joint>
  <link name="left_arm_shoulder_link">
    <visual>
      <origin rpy="0 0 3.141592653589793" xyz="0 0 0"/>
      <geometry>
        <mesh filename="package://ur_description/meshes/ur3/visual/shoulder.dae"/>
      </geometry>
      <material name="LightGrey">
        <color rgba="0.7 0.7 0.7 1.0"/>
      </material>
    </visual>
    <collision>
      <origin rpy="0 0 3.141592653589793" xyz="0 0 0"/>
      <geometry>
        <mesh filename="package://ur_description/meshes/ur3/collision/shoulder.stl"/>
      </geometry>
    </collision>
    <inertial>
      <mass value="2.0"/>
      <origin rpy="0 0 0" xyz="0.0 0.0 0.0"/>
      <inertia ixx="0.008093163429399999" ixy="0.0" ixz="0.0" iyy="0.008093163429399999" iyz="0.0" izz="0.005625"/>
    </inertial>
  </link>
  <joint name="left_arm_shoulder_lift_joint" type="revolute">
    <parent link="left_arm_shoulder_link"/>
    <child link="left_arm_upper_arm_link"/>
    <origin rpy="1.570796327 0 0" xyz="0 0 0"/>
    <axis xyz="0 0 1"/>
    <limit effort="330.0" lower="-3.141592653589793" upper="3.141592653589793" velocity="2.16"/>
    <dynamics damping="0.0" friction="0.0"/>
  </joint>
  <link name="left_arm_upper_arm_link">
    <visual>
      <origin rpy="1.5707963267948966 0 -1.5707963267948966" xyz="0 0 0.1198"/>
      <geometry>
        <mesh filename="package://ur_description/meshes/ur3/visual/upperarm.dae"/>
      </geometry>
      <material name="LightGrey">
        <color rgba="0.7 0.7 0.7 1.0"/>
      </material>
    </visual>
    <collision>
      <origin rpy="1.5707963267948966 0 -1.5707963267948966" xyz="0 0 0.1198"/>
      <geometry>
        <mesh filename="package://ur_description/meshes/ur3/collision/upperarm.stl"/>
      </geometry>
    </collision>
    <inertial>
      <mass value="3.42"/>
      <origin rpy="0 1.5707963267948966 0" xyz="-0.121825 0.0 0.12"/>
      <inertia ixx="0.021728483221103233" ixy="0.0" ixz="0.0" iyy="0.021728483221103233" iyz="0.0" izz="0.00961875"/>
    </inertial>
  </link>
  <joint name="left_arm_elbow_joint" type="revolute">
    <parent link="left_arm_upper_arm_link"/>
    <child link="left_arm_forearm_link"/>
    <origin rpy="0 0 0" xyz="-0.24365 0 0"/>
    <axis xyz="0 0 1"/>
    <limit effort="150.0" lower="-3.141592653589793" upper="3.141592653589793" velocity="3.15"/>
    <dynamics damping="0.0" friction="0.0"/>
  </joint>
  <link name="left_arm_forearm_link">
    <visual>
      <origin rpy="1.5707963267948966 0 -1.5707963267948966" xyz="0 0 0.0275"/>
      <geometry>
        <mesh filename="package://ur_description/meshes/ur3/visual/forearm.dae"/>
      </geometry>
      <material name="LightGrey">
        <color rgba="0.7 0.7 0.7 1.0"/>
      </material>
    </visual>
    <collision>
      <origin rpy="1.5707963267948966 0 -1.5707963267948966" xyz="0 0 0.0275"/>
      <geometry>
        <mesh filename="package://ur_description/meshes/ur3/collision/forearm.stl"/>
      </geometry>
    </collision>
    <inertial>
      <mass value="1.26"/>
      <origin rpy="0 1.5707963267948966 0" xyz="-0.121825 0.0 0.0275"/>
      <inertia ixx="0.006546806443776375" ixy="0.0" ixz="0.0" iyy="0.006546806443776375" iyz="0.0" izz="0.00354375"/>
    </inertial>
  </link>
  <joint name="left_arm_wrist_1_joint" type="revolute">
    <parent link="left_arm_forearm_link"/>
    <child link="left_arm_wrist_1_link"/>
    <origin rpy="0 0 0" xyz="-0.21325 0 0.11235"/>
    <axis xyz="0 0 1"/>
    <limit effort="54.0" lower="-3.141592653589793" upper="3.141592653589793" velocity="3.2"/>
    <dynamics damping="0.0" friction="0.0"/>
  </joint>
  <link name="left_arm_wrist_1_link">
    <visual>
      <origin rpy="1.5707963267948966 0 0" xyz="0 0 -0.085"/>
      <geometry>
        <mesh filename="package://ur_description/meshes/ur3/visual/wrist1.dae"/>
      </geometry>
      <material name="LightGrey">
        <color rgba="0.7 0.7 0.7 1.0"/>
      </material>
    </visual>
    <collision>
      <origin rpy="1.5707963267948966 0 0" xyz="0 0 -0.085"/>
      <geometry>
        <mesh filename="package://ur_description/meshes/ur3/collision/wrist1.stl"/>
      </geometry>
    </collision>
    <inertial>
      <mass value="0.8"/>
      <origin rpy="0 0 0" xyz="0.0 0.0 0.0"/>
      <inertia ixx="0.0016106408557434" ixy="0.0" ixz="0.0" iyy="0.0016106408557434" iyz="0.0" izz="0.00225"/>
    </inertial>
  </link>
  <joint name="left_arm_wrist_2_joint" type="revolute">
    <parent link="left_arm_wrist_1_link"/>
    <child link="left_arm_wrist_2_link"/>
    <origin rpy="1.570796327 0 0" xyz="0 -0.08535 -1.750557762378351e-11"/>
    <axis xyz="0 0 1"/>
    <limit effort="54.0" lower="-3.141592653589793" upper="3.141592653589793" velocity="3.2"/>
    <dynamics damping="0.0" friction="0.0"/>
  </joint>
  <link name="left_arm_wrist_2_link">
    <visual>
      <origin rpy="0 0 0" xyz="0 0 -0.085"/>
      <geometry>
        <mesh filename="package://ur_description/meshes/ur3/visual/wrist2.dae"/>
      </geometry>
      <material name="LightGrey">
        <color rgba="0.7 0.7 0.7 1.0"/>
      </material>
    </visual>
    <collision>
      <origin rpy="0 0 0" xyz="0 0 -0.085"/>
      <geometry>
        <mesh filename="package://ur_description/meshes/ur3/collision/wrist2.stl"/>
      </geometry>
    </collision>
    <inertial>
      <mass value="0.8"/>
      <origin rpy="0 0 0" xyz="0.0 0.0 0.0"/>
      <inertia ixx="0.0015721733711303997" ixy="0.0" ixz="0.0" iyy="0.0015721733711303997" iyz="0.0" izz="0.00225"/>
    </inertial>
  </link>
  <joint name="left_arm_wrist_3_joint" type="revolute">
    <parent link="left_arm_wrist_2_link"/>
    <child link="left_arm_wrist_3_link"/>
    <origin rpy="1.570796326589793 3.141592653589793 3.141592653589793" xyz="0 0.0819 -1.679797079540562e-11"/>
    <axis xyz="0 0 1"/>
    <limit effort="54.0" lower="-3.141592653589793" upper="3.141592653589793" velocity="3.2"/>
    <dynamics damping="0.0" friction="0.0"/>
  </joint>
  <link name="left_arm_wrist_3_link">
    <visual>
      <origin rpy="1.5707963267948966 0 0" xyz="0 0 -0.082"/>
      <geometry>
        <mesh filename="package://ur_description/meshes/ur3/visual/wrist3.dae"/>
      </geometry>
      <material name="LightGrey">
        <color rgba="0.7 0.7 0.7 1.0"/>
      </material>
    </visual>
    <collision>
      <origin rpy="1.5707963267948966 0 0" xyz="0 0 -0.082"/>
      <geometry>
        <mesh filename="package://ur_description/meshes/ur3/collision/wrist3.stl"/>
      </geometry>
    </collision>
    <inertial>
      <mass value="0.35"/>
      <origin rpy="0 0 0" xyz="0.0 0.0 -0.01525"/>
      <inertia ixx="0.00020431970993874997" ixy="0.0" ixz="0.0" iyy="0.00020431970993874997" iyz="0.0" izz="0.000354375"/>
    </inertial>
  </link>
  <joint name="left_arm_ee_fixed_joint" type="fixed">
    <parent link="left_arm_wrist_3_link"/>
    <child link="left_arm_ee_link"/>
    <origin rpy="0.0 -1.5707963267948966 1.5707963267948966" xyz="0.0 0.0 0.0"/>
  </joint>
  <link name="left_arm_ee_link">
    <collision>
      <geometry>
        <box size="0.01 0.01 0.01"/>
      </geometry>
      <origin rpy="0 0 0" xyz="-0.01 0 0"/>
    </collision>
  </link>
  <joint name="left_arm_wrist_3_passive_joint" type="fixed">
    <origin rpy="0 0 0" xyz="0 0 0"/>
    <parent link="left_arm_wrist_3_link"/>
    <child link="left_arm_tool0"/>
  </joint>
  <transmission name="left_arm_shoulder_pan_trans">
    <type>transmission_interface/SimpleTransmission</type>
    <joint name="left_arm_shoulder_pan_joint">
      <hardwareInterface>hardware_interface/PositionJointInterface</hardwareInterface>
    </joint>
    <actuator name="left_arm_shoulder_pan_motor">
      <mechanicalReduction>1</mechanicalReduction>
    </actuator>
  </transmission>
  <transmission name="left_arm_shoulder_lift_trans">
    <type>transmission_interface/SimpleTransmission</type>
    <joint name="left_arm_shoulder_lift_joint">
      <hardwareInterface>hardware_interface/PositionJointInterface</hardwareInterface>
    </joint>
    <actuator name="left_arm_shoulder_lift_motor">
      <mechanicalReduction>1</mechanicalReduction>
    </actuator>
  </transmission>
  <transmission name="left_arm_elbow_trans">
    <type>transmission_interface/SimpleTransmission</type>
    <joint name="left_arm_elbow_joint">
      <hardwareInterface>hardware_interface/PositionJointInterface</hardwareInterface>
    </joint>
    <actuator name="left_arm_elbow_motor">
      <mechanicalReduction>1</mechanicalReduction>
    </actuator>
  </transmission>
  <transmission name="left_arm_wrist_1_trans">
    <type>transmission_interface/SimpleTransmission</type>
    <joint name="left_arm_wrist_1_joint">
      <hardwareInterface>hardware_interface/PositionJointInterface</hardwareInterface>
    </joint>
    <actuator name="left_arm_wrist_1_motor">
      <mechanicalReduction>1</mechanicalReduction>
    </actuator>
  </transmission>
  <transmission name="left_arm_wrist_2_trans">
    <type>transmission_interface/SimpleTransmission</type>
    <joint name="left_arm_wrist_2_joint">
      <hardwareInterface>hardware_interface/PositionJointInterface</hardwareInterface>
    </joint>
    <actuator name="left_arm_wrist_2_motor">
      <mechanicalReduction>1</mechanicalReduction>
    </actuator>
  </transmission>
  <transmission name="left_arm_wrist_3_trans">
    <type>transmission_interface/SimpleTransmission</type>
    <joint name="left_arm_wrist_3_joint">
      <hardwareInterface>hardware_interface/PositionJointInterface</hardwareInterface>
    </joint>
    <actuator name="left_arm_wrist_3_motor">
      <mechanicalReduction>1</mechanicalReduction>
    </actuator>
  </transmission>
  <gazebo reference="left_arm_shoulder_link">
    <selfCollide>true</selfCollide>
  </gazebo>
  <gazebo reference="left_arm_upper_arm_link">
    <selfCollide>true</selfCollide>
  </gazebo>
  <gazebo reference="left_arm_forearm_link">
    <selfCollide>true</selfCollide>
  </gazebo>
  <gazebo reference="left_arm_wrist_1_link">
    <selfCollide>true</selfCollide>
  </gazebo>
  <gazebo reference="left_arm_wrist_3_link">
    <selfCollide>true</selfCollide>
  </gazebo>
  <gazebo reference="left_arm_wrist_2_link">
    <selfCollide>true</selfCollide>
  </gazebo>
  <gazebo reference="left_arm_ee_link">
    <selfCollide>true</selfCollide>
  </gazebo>
  <!-- ROS base_link to UR 'Base' Coordinates transform -->
  <!--link name="left_arm_base"/>
  <joint name="left_arm_base_link-base_fixed_joint" type="fixed">
    <origin rpy="0 0 -3.141592653589793" xyz="0 0 0"/>
    <parent link="left_arm_base_link"/>
    <child link="left_arm_base"/>
  </joint-->
  <!-- Frame coincident with all-zeros TCP on UR controller -->
  <link name="left_arm_tool0"/>
  <!-- JOINT IZQUEIRDA DEL ROBOT -->
  <joint name="left_arm_base_joint" type="fixed">
	<origin xyz="0.0 0.0 0.0" rpy="0.0 0.0 0.0"/>
	<parent link="torso_ur3_left_link" />
	<child link="left_arm_base_link" />
</joint>
  
</robot>


