<?xml version="1.0" ?>
<!-- =================================================================================== -->
<!-- |    This document was autogenerated by xacro from rb1_dual_ur3.urdf.xacro        | -->
<!-- |    EDITING THIS FILE BY HAND IS NOT RECOMMENDED                                 | -->
<!-- =================================================================================== -->
<robot name="rb1_base">
  <!-- ***************** -->
  <!-- Imported elements -->
  <!-- ***************** -->
  <!-- First we import all posible elements defined in the urdf.xacro files. All these elements are defined as macro:xacros -->
  <!-- v3 name from engineering department -->
  <!--
  Author: Felix Messmer
-->
  <!-- in kg-->
  <!-- in kg-->
  <!-- This file unifies all sensors that can be used on simulation, defined as xacro:macros -->
  <!-- Includes -->
  <!-- *************** -->
  <!-- Robots Elements -->
  <!-- *************** -->
  <!-- Here we create the robot elements using the xacro:macros imported at the beggining of this file -->
  <link name="rb1_base_footprint">
    <inertial>
      <mass value="1.0"/>
      <origin rpy="0 0 0" xyz="0 0 0"/>
      <inertia ixx="0.01" ixy="0.0" ixz="0.0" iyy="0.01" iyz="0.0" izz="0.01"/>
    </inertial>
    <visual>
      <origin rpy="0 0 0" xyz="0 0 0"/>
      <geometry>
        <box size="0.001 0.001 0.001"/>
      </geometry>
    </visual>
  </link>
  <!-- BASE_LINK -->
  <link name="rb1_base_link">
    <inertial>
      <mass value="25.0"/>
      <origin xyz="0 0 0"/>
      <inertia ixx="0.605" ixy="0.0" ixz="0.0" iyy="0.5435" iyz="0.0" izz="0.981"/>
    </inertial>
    <visual>
      <origin rpy="0 0 0" xyz="0 0 0"/>
      <geometry>
        <mesh filename="package://rb1_base_description/meshes/bases/rb1_base_v3.stl"/>
      </geometry>
      <material name="darkgrey">
        <color rgba="0.1 0.1 0.1 1"/>
      </material>
    </visual>
    <!--collision>
        <origin xyz="0 0 0" rpy="0 0 0 " />
        <geometry>
          <mesh filename="package://rb1_base_description/meshes/bases/rb1_base_v3.dae"/>
        </geometry>
      </collision-->
  </link>
  <joint name="rb1_base_footprint_joint" type="fixed">
    <origin rpy="0 0 0" xyz="0 0 0.024799999999999996"/>
    <parent link="rb1_base_footprint"/>
    <child link="rb1_base_link"/>
  </joint>
  <!-- FRONT COVER -->
  <link name="rb1_front_cover_link">
    <inertial>
      <mass value="0.25"/>
      <origin xyz="0 0 0"/>
      <inertia ixx="0.00007" ixy="0.0" ixz="0.0" iyy="0.00007" iyz="0.0" izz="0.0078"/>
    </inertial>
    <visual>
      <origin rpy="0 0 0" xyz="0 0 0"/>
      <geometry>
        <mesh filename="package://rb1_base_description/meshes/bases/rb1_front_cover_v3.stl"/>
      </geometry>
      <material name="black">
        <color rgba="0.0 0.0 0.0 1"/>
      </material>
    </visual>
    <collision>
      <origin rpy="0 0 0 " xyz="0 0 0"/>
      <geometry>
        <mesh filename="package://rb1_base_description/meshes/bases/rb1_front_cover_v3.dae"/>
      </geometry>
    </collision>
  </link>
  <joint name="rb1_front_cover_joint" type="fixed">
    <origin rpy="0 0 0 " xyz="0.220 0.0 0.004"/>
    <parent link="rb1_base_link"/>
    <child link="rb1_front_cover_link"/>
  </joint>
  <!-- FRONT COVER -->
  <link name="rb1_top_cover_link">
    <inertial>
      <mass value="0.25"/>
      <origin xyz="0 0 0"/>
      <inertia ixx="0.00007" ixy="0.0" ixz="0.0" iyy="0.00007" iyz="0.0" izz="0.0078"/>
    </inertial>
    <visual>
      <origin rpy="0 0 0" xyz="0 0 0"/>
      <geometry>
        <mesh filename="package://rb1_base_description/meshes/bases/rb1_top_cover_v3.stl"/>
      </geometry>
      <material name="black">
        <color rgba="0.0 0.0 0.0 1"/>
      </material>
    </visual>
    <collision>
      <origin rpy="0 0 0 " xyz="0 0 0"/>
      <geometry>
        <mesh filename="package://rb1_base_description/meshes/bases/rb1_top_cover_v3.dae"/>
      </geometry>
    </collision>
  </link>
  <joint name="rb1_top_covert_joint" type="fixed">
    <origin rpy="0 0 0 " xyz="0.0 0.0 0.243"/>
    <parent link="rb1_base_footprint"/>
    <child link="rb1_top_cover_link"/>
  </joint>
  <!-- DOCKING LINK -->
  <link name="rb1_base_docking_contact_link">
    <inertial>
      <mass value="0.1"/>
      <origin rpy="0 0 0" xyz="0 0 0"/>
      <inertia ixx="0.001" ixy="0.0" ixz="0.0" iyy="0.001" iyz="0.0" izz="0.001"/>
    </inertial>
  </link>
  <!-- DOCKING CONTACTS -->
  <joint name="rb1_base_docking_joint" type="fixed">
    <origin rpy="0 0 0 " xyz="0.030 0.000 0.068"/>
    <parent link="rb1_front_cover_link"/>
    <child link="rb1_base_docking_contact_link"/>
  </joint>
  <gazebo>
    <plugin filename="libgazebo_ros_control.so" name="ros_control">
      <!--robotNamespace>/rb1</robotNamespace-->
      <robotParam>robot_description</robotParam>
      <controlPeriod>0.001</controlPeriod>
      <robotSimType>gazebo_ros_control/DefaultRobotHWSim</robotSimType>
      <legacyModeNS>true</legacyModeNS>
    </plugin>
  </gazebo>
  <gazebo reference="rb1_base_footprint">
    <material>Gazebo/Green</material>
  </gazebo>
  <gazebo reference="rb1_base_link">
    <material>Gazebo/Black</material>
  </gazebo>
  <gazebo reference="rb1_front_cover_link">
    <material>Gazebo/Black</material>
  </gazebo>
  <!--WHEEL TIRE -->
  <link name="rb1_right_wheel_link">
    <visual>
      <origin rpy="0 0 0" xyz="0 0 0"/>
      <geometry>
        <mesh filename="package://rb1_base_description/meshes/wheels/wheel_rubber_6inch.dae"/>
      </geometry>
    </visual>
    <collision>
      <origin rpy="1.5707963267948966 0 0" xyz="0 0 0"/>
      <geometry>
        <cylinder length="0.025" radius="0.076"/>
      </geometry>
    </collision>
    <inertial>
      <mass value="1.0"/>
      <origin rpy="1.5707963267948966 0 0" xyz="0 0 0"/>
      <inertia ixx="0.0014960833333333334" ixy="0" ixz="0" iyy="0.0014960833333333334" iyz="0" izz="0.002888"/>
    </inertial>
  </link>
  <joint name="rb1_right_wheel_joint" type="continuous">
    <parent link="rb1_base_link"/>
    <child link="rb1_right_wheel_link"/>
    <origin rpy="0 0 0" xyz="0.0 -0.218 0.0512"/>
    <axis rpy="0 0 0" xyz="0 1 0"/>
    <limit effort="100" velocity="100"/>
    <joint_properties damping="0.0" friction="0.0"/>
  </joint>
  <!-- Transmission is important to link the joints and the controller (see rb1_control/config/rb1_control.yaml)-->
  <transmission name="rb1_right_wheel_joint_trans">
    <type>transmission_interface/SimpleTransmission</type>
    <joint name="rb1_right_wheel_joint">
      <!-- for the gazebo plugin -->
      <!--hardwareInterface>EffortJointInterface</hardwareInterface-->
      <!-- for ros control controller -->
      <hardwareInterface>hardware_interface/VelocityJointInterface</hardwareInterface>
    </joint>
    <actuator name="rb1_right_wheel_joint_motor">
      <mechanicalReduction>1</mechanicalReduction>
      <motorTorqueConstant>20</motorTorqueConstant>
    </actuator>
  </transmission>
  <gazebo reference="rb1_right_wheel_link">
    <mu1 value="5.0"/>
    <mu2 value="0.5"/>
    <kp value="10000000.0"/>
    <kd value="1.0"/>
    <fdir1 value="1 0 0"/>
    <material>Gazebo/Yellow</material>
    <turnGravityOff>false</turnGravityOff>
    <!--kp>500000.0</kp>
			<kd>10.0</kd>
			<mu1>10</mu1>
			<mu2>10</mu2>
			<fdir1>1 0 0</fdir1-->
    <!--minDepth>0.001</minDepth-->
    <!--material>Gazebo/Black</material-->
    <!--mu1 value="10"/>
			<mu2 value="5"/>
			<kp value="500000.0" />
			<kd value="10.0" />
			<fdir1 value="1 0 0"/>
			<material>Gazebo/Yellow</material>
			<turnGravityOff>false</turnGravityOff-->
  </gazebo>
  <!--gazebo reference="${name}_wheel_link">
			<kp>500000.0</kp>
			<kd>10.0</kd>
			<mu1>10</mu1>
			<mu2>10</mu2>
			<fdir1>1 0 0</fdir1>
			<maxVel>1.0</maxVel>
			<minDepth>0.003</minDepth>
			<material>Gazebo/Yellow</material>
			<turnGravityOff>false</turnGravityOff>
			<implicitSpringDamper>1</implicitSpringDamper>
		</gazebo-->
  <!--WHEEL TIRE -->
  <link name="rb1_left_wheel_link">
    <visual>
      <origin rpy="0 0 0" xyz="0 0 0"/>
      <geometry>
        <mesh filename="package://rb1_base_description/meshes/wheels/wheel_rubber_6inch.dae"/>
      </geometry>
    </visual>
    <collision>
      <origin rpy="1.5707963267948966 0 0" xyz="0 0 0"/>
      <geometry>
        <cylinder length="0.025" radius="0.076"/>
      </geometry>
    </collision>
    <inertial>
      <mass value="1.0"/>
      <origin rpy="1.5707963267948966 0 0" xyz="0 0 0"/>
      <inertia ixx="0.0014960833333333334" ixy="0" ixz="0" iyy="0.0014960833333333334" iyz="0" izz="0.002888"/>
    </inertial>
  </link>
  <joint name="rb1_left_wheel_joint" type="continuous">
    <parent link="rb1_base_link"/>
    <child link="rb1_left_wheel_link"/>
    <origin rpy="0 0 0" xyz="0.0 0.218 0.0512"/>
    <axis rpy="0 0 0" xyz="0 1 0"/>
    <limit effort="100" velocity="100"/>
    <joint_properties damping="0.0" friction="0.0"/>
  </joint>
  <!-- Transmission is important to link the joints and the controller (see rb1_control/config/rb1_control.yaml)-->
  <transmission name="rb1_left_wheel_joint_trans">
    <type>transmission_interface/SimpleTransmission</type>
    <joint name="rb1_left_wheel_joint">
      <!-- for the gazebo plugin -->
      <!--hardwareInterface>EffortJointInterface</hardwareInterface-->
      <!-- for ros control controller -->
      <hardwareInterface>hardware_interface/VelocityJointInterface</hardwareInterface>
    </joint>
    <actuator name="rb1_left_wheel_joint_motor">
      <mechanicalReduction>1</mechanicalReduction>
      <motorTorqueConstant>20</motorTorqueConstant>
    </actuator>
  </transmission>
  <gazebo reference="rb1_left_wheel_link">
    <mu1 value="5.0"/>
    <mu2 value="0.5"/>
    <kp value="10000000.0"/>
    <kd value="1.0"/>
    <fdir1 value="1 0 0"/>
    <material>Gazebo/Yellow</material>
    <turnGravityOff>false</turnGravityOff>
    <!--kp>500000.0</kp>
			<kd>10.0</kd>
			<mu1>10</mu1>
			<mu2>10</mu2>
			<fdir1>1 0 0</fdir1-->
    <!--minDepth>0.001</minDepth-->
    <!--material>Gazebo/Black</material-->
    <!--mu1 value="10"/>
			<mu2 value="5"/>
			<kp value="500000.0" />
			<kd value="10.0" />
			<fdir1 value="1 0 0"/>
			<material>Gazebo/Yellow</material>
			<turnGravityOff>false</turnGravityOff-->
  </gazebo>
  <!--gazebo reference="${name}_wheel_link">
			<kp>500000.0</kp>
			<kd>10.0</kd>
			<mu1>10</mu1>
			<mu2>10</mu2>
			<fdir1>1 0 0</fdir1>
			<maxVel>1.0</maxVel>
			<minDepth>0.003</minDepth>
			<material>Gazebo/Yellow</material>
			<turnGravityOff>false</turnGravityOff>
			<implicitSpringDamper>1</implicitSpringDamper>
		</gazebo-->
  <!--WHEEL TIRE -->
  <link name="rb1_omni_backwheel_link">
    <visual>
      <origin rpy="0 0 0" xyz="0 0 0"/>
      <geometry>
        <mesh filename="package://rb1_base_description/meshes/wheels/rb1v2_omniwheel.dae"/>
      </geometry>
    </visual>
    <collision>
      <origin rpy="1.5707963267948966 0 0" xyz="0 0 0"/>
      <geometry>
        <cylinder length="0.03" radius="0.051"/>
      </geometry>
    </collision>
    <!--collision>
      <origin xyz="0 0 0" rpy="${M_PI/2} 0 0" />
       <geometry>
         <sphere radius="${omni_wheel_radius}"/>
       </geometry>
     </collision-->
    <inertial>
      <mass value="1.0"/>
      <origin xyz="0 0 0"/>
      <inertia ixx="0.00023507499999999998" ixy="0" ixz="0" iyy="0.00023507499999999998" iyz="0" izz="0.0003901499999999999"/>
      <!-- inertia  ixx="0.001" ixy="0.0"  ixz="0.0"  iyy="0.001"  iyz="0.0"  izz="0.001" / -->
    </inertial>
  </link>
  <!-- joint name="joint_${name}_wheel" type="continuous" -->
  <joint name="rb1_omni_backwheel_joint" type="fixed">
    <parent link="rb1_base_link"/>
    <child link="rb1_omni_backwheel_link"/>
    <origin rpy="0 0 0" xyz="-0.195 0.0 0.027"/>
    <axis rpy="0 0 0" xyz="0 1 0"/>
    <limit effort="100" velocity="100"/>
    <joint_properties damping="0.0" friction="0.0"/>
  </joint>
  <!-- transmission name="${name}_wheel_joint_trans">
      <type>transmission_interface/SimpleTransmission</type>
      <joint name="joint_${name}_wheel" />
      <actuator name="${name}_wheel_joint_motor">
        <hardwareInterface>EffortJointInterface</hardwareInterface>
        <mechanicalReduction>1</mechanicalReduction>
      </actuator>
    </transmission -->
  <gazebo reference="rb1_omni_backwheel">
    <mu1 value="0"/>
    <mu2 value="0"/>
    <kp value="10000000.0"/>
    <kd value="1.0"/>
    <fdir1 value="1 0 0"/>
    <material>Gazebo/Black</material>
    <turnGravityOff>false</turnGravityOff>
  </gazebo>
  <!--gazebo reference="${name}_wheel">
		<kp>500000.0</kp>
		<kd>10.0</kd>
		<mu1>10</mu1>
		<mu2>10</mu2>
		<fdir1>1 0 0</fdir1>
		<maxVel>1.0</maxVel>
		<minDepth>0.003</minDepth>
		<material>Gazebo/Black</material>
		<turnGravityOff>false</turnGravityOff>
		<implicitSpringDamper>1</implicitSpringDamper>
    </gazebo-->
  <!--WHEEL TIRE -->
  <link name="rb1_omni_front_leftwheel_link">
    <visual>
      <origin rpy="0 0 0" xyz="0 0 0"/>
      <geometry>
        <mesh filename="package://rb1_base_description/meshes/wheels/rb1v2_omniwheel.dae"/>
      </geometry>
    </visual>
    <collision>
      <origin rpy="1.5707963267948966 0 0" xyz="0 0 0"/>
      <geometry>
        <cylinder length="0.03" radius="0.051"/>
      </geometry>
    </collision>
    <!--collision>
      <origin xyz="0 0 0" rpy="${M_PI/2} 0 0" />
       <geometry>
         <sphere radius="${omni_wheel_radius}"/>
       </geometry>
     </collision-->
    <inertial>
      <mass value="1.0"/>
      <origin xyz="0 0 0"/>
      <inertia ixx="0.00023507499999999998" ixy="0" ixz="0" iyy="0.00023507499999999998" iyz="0" izz="0.0003901499999999999"/>
      <!-- inertia  ixx="0.001" ixy="0.0"  ixz="0.0"  iyy="0.001"  iyz="0.0"  izz="0.001" / -->
    </inertial>
  </link>
  <!-- joint name="joint_${name}_wheel" type="continuous" -->
  <joint name="rb1_omni_front_leftwheel_joint" type="fixed">
    <parent link="rb1_base_link"/>
    <child link="rb1_omni_front_leftwheel_link"/>
    <origin rpy="0 0 0" xyz="0.132 0.1535 0.027"/>
    <axis rpy="0 0 0" xyz="0 1 0"/>
    <limit effort="100" velocity="100"/>
    <joint_properties damping="0.0" friction="0.0"/>
  </joint>
  <!-- transmission name="${name}_wheel_joint_trans">
      <type>transmission_interface/SimpleTransmission</type>
      <joint name="joint_${name}_wheel" />
      <actuator name="${name}_wheel_joint_motor">
        <hardwareInterface>EffortJointInterface</hardwareInterface>
        <mechanicalReduction>1</mechanicalReduction>
      </actuator>
    </transmission -->
  <gazebo reference="rb1_omni_front_leftwheel">
    <mu1 value="0"/>
    <mu2 value="0"/>
    <kp value="10000000.0"/>
    <kd value="1.0"/>
    <fdir1 value="1 0 0"/>
    <material>Gazebo/Black</material>
    <turnGravityOff>false</turnGravityOff>
  </gazebo>
  <!--gazebo reference="${name}_wheel">
		<kp>500000.0</kp>
		<kd>10.0</kd>
		<mu1>10</mu1>
		<mu2>10</mu2>
		<fdir1>1 0 0</fdir1>
		<maxVel>1.0</maxVel>
		<minDepth>0.003</minDepth>
		<material>Gazebo/Black</material>
		<turnGravityOff>false</turnGravityOff>
		<implicitSpringDamper>1</implicitSpringDamper>
    </gazebo-->
  <!--WHEEL TIRE -->
  <link name="rb1_omni_front_rightwheel_link">
    <visual>
      <origin rpy="0 0 0" xyz="0 0 0"/>
      <geometry>
        <mesh filename="package://rb1_base_description/meshes/wheels/rb1v2_omniwheel.dae"/>
      </geometry>
    </visual>
    <collision>
      <origin rpy="1.5707963267948966 0 0" xyz="0 0 0"/>
      <geometry>
        <cylinder length="0.03" radius="0.051"/>
      </geometry>
    </collision>
    <!--collision>
      <origin xyz="0 0 0" rpy="${M_PI/2} 0 0" />
       <geometry>
         <sphere radius="${omni_wheel_radius}"/>
       </geometry>
     </collision-->
    <inertial>
      <mass value="1.0"/>
      <origin xyz="0 0 0"/>
      <inertia ixx="0.00023507499999999998" ixy="0" ixz="0" iyy="0.00023507499999999998" iyz="0" izz="0.0003901499999999999"/>
      <!-- inertia  ixx="0.001" ixy="0.0"  ixz="0.0"  iyy="0.001"  iyz="0.0"  izz="0.001" / -->
    </inertial>
  </link>
  <!-- joint name="joint_${name}_wheel" type="continuous" -->
  <joint name="rb1_omni_front_rightwheel_joint" type="fixed">
    <parent link="rb1_base_link"/>
    <child link="rb1_omni_front_rightwheel_link"/>
    <origin rpy="0 0 0" xyz="0.132 -0.1535 0.027"/>
    <axis rpy="0 0 0" xyz="0 1 0"/>
    <limit effort="100" velocity="100"/>
    <joint_properties damping="0.0" friction="0.0"/>
  </joint>
  <!-- transmission name="${name}_wheel_joint_trans">
      <type>transmission_interface/SimpleTransmission</type>
      <joint name="joint_${name}_wheel" />
      <actuator name="${name}_wheel_joint_motor">
        <hardwareInterface>EffortJointInterface</hardwareInterface>
        <mechanicalReduction>1</mechanicalReduction>
      </actuator>
    </transmission -->
  <gazebo reference="rb1_omni_front_rightwheel">
    <mu1 value="0"/>
    <mu2 value="0"/>
    <kp value="10000000.0"/>
    <kd value="1.0"/>
    <fdir1 value="1 0 0"/>
    <material>Gazebo/Black</material>
    <turnGravityOff>false</turnGravityOff>
  </gazebo>
  <!--gazebo reference="${name}_wheel">
		<kp>500000.0</kp>
		<kd>10.0</kd>
		<mu1>10</mu1>
		<mu2>10</mu2>
		<fdir1>1 0 0</fdir1>
		<maxVel>1.0</maxVel>
		<minDepth>0.003</minDepth>
		<material>Gazebo/Black</material>
		<turnGravityOff>false</turnGravityOff>
		<implicitSpringDamper>1</implicitSpringDamper>
    </gazebo-->
  <!-- SENSORS -->
  <link name="rb1_front_laser_link">
  <inertial>
      <mass value="0.0"/>
      <origin rpy="0 0 0" xyz="0 0 0"/>
      <inertia ixx="0.0" ixy="0.0" ixz="0.0" iyy="0.0" iyz="0.0" izz="0.0"/>
    </inertial>
	</link>
  <joint name="rb1_front_laser_joint" type="fixed">
    <parent link="rb1_base_link"/>
    <child link="rb1_front_laser_link"/>
    <origin rpy="0 3.1416 3.1416" xyz="0.210 0.0 0.159"/>
  </joint>
  <joint name="rb1_front_laser_base_joint" type="fixed">
    <origin rpy="0 0 0" xyz="0.00 0 -0.05"/>
    <parent link="rb1_front_laser_link"/>
    <child link="rb1_front_laser_base_link"/>
  </joint>
  <link name="rb1_front_laser_base_link">
    <collision>
      <origin rpy="0 0 0" xyz="0 0 0.0"/>
      <geometry>
        <box size="0.010 0.010 0.010"/>
      </geometry>
    </collision>
    <visual>
      <origin rpy="0 0 0" xyz="0 0 0.0"/>
      <geometry>
        <mesh filename="package://robotnik_sensors/meshes/hokuyo_ust_10lx.dae"/>
      </geometry>
    </visual>
    <inertial>
      <mass value="1e-5"/>
      <origin rpy="0 0 0" xyz="0 0 0"/>
      <inertia ixx="1e-6" ixy="0" ixz="0" iyy="1e-6" iyz="0" izz="1e-6"/>
    </inertial>
  </link>
  <gazebo reference="rb1_front_laser_link">
    <sensor name="rb1_front_laser_sensor" type="gpu_ray">
      <pose>0 0 0 0 0 0</pose>
      <visualize>false</visualize>
      <update_rate>40</update_rate>
      <ray>
        <scan>
          <horizontal>
            <samples>1081</samples>
            <resolution>1</resolution>
            <min_angle>-2.3562</min_angle>
            <max_angle>2.3562</max_angle>
          </horizontal>
        </scan>
        <range>
          <min>0.06</min>
          <max>10.0</max>
          <!-- resolution>0.004363323</resolution -->
          <resolution>0.004359297</resolution>
          <!-- resolution>0.001</resolution -->
        </range>
        <noise>
          <type>gaussian</type>
          <mean>0.0</mean>
          <stddev>0.01</stddev>
        </noise>
      </ray>
      <plugin filename="libgazebo_ros_gpu_laser.so" name="rb1_front_laser_controller">
        <topicName>front_laser/scan</topicName>
        <frameName>/rb1_front_laser_link</frameName>
      </plugin>
    </sensor>
  </gazebo>
  <joint name="rb1_imu_joint" type="fixed">
    <axis xyz="1 0 0"/>
    <!--origin xyz="0 0 0.2825"/-->
    <origin rpy="0 0 0" xyz="0.002 0.053 0.1485"/>
    <parent link="rb1_base_link"/>
    <child link="rb1_imu_link"/>
  </joint>
  <link name="rb1_imu_link">
    <inertial>
      <mass value="0.001"/>
      <origin rpy="0 0 0" xyz="0 0 0"/>
      <inertia ixx="0.0001" ixy="0" ixz="0" iyy="0.000001" iyz="0" izz="0.0001"/>
    </inertial>
    <visual>
      <origin rpy="0 0 0" xyz="0 0 0"/>
      <geometry>
        <box size="0.001 0.001 0.001"/>
      </geometry>
    </visual>
    <collision>
      <origin rpy="0 0 0" xyz="0 0 0"/>
      <geometry>
        <box size=".001 .001 .001"/>
      </geometry>
    </collision>
  </link>
  <gazebo>
    <plugin filename="libhector_gazebo_ros_imu.so" name="rb1_imu_controller">
      <alwaysOn>true</alwaysOn>
      <topicName>imu/data</topicName>
      <serviceName>rb1_imuimu/service</serviceName>
      <bodyName>rb1_imu_link</bodyName>
      <frameId>rb1_imu_link</frameId>
      <updateRate>50.0</updateRate>
      <gaussianNoise>0.00</gaussianNoise>
      <yawOffset>0.0</yawOffset>
      <yawDrift>0.0</yawDrift>
      <yawGaussianNoise>0.0</yawGaussianNoise>
      <!-- angular velocities parameters -->
      <rateOffset>0.0 0.0 0.0</rateOffset>
      <rateDrift>0.0 0.0 0.0</rateDrift>
      <rateGaussianNoise>0.0 0.0 0.0</rateGaussianNoise>
      <!-- linear accelerations parameters -->
      <accelOffset>0.0 0.0 0.0</accelOffset>
      <accelDrift>0.0 0.0 0.0</accelDrift>
      <accelGaussianNoise>0.0 0.0 0.0</accelGaussianNoise>
    </plugin>
  </gazebo>
  <joint name="rb1_front_rgbd_camera_rgb_joint" type="fixed">
    <origin rpy="0 0 0" xyz="0.234 0.0125 0.107"/>
    <parent link="rb1_base_link"/>
    <child link="rb1_front_rgbd_camera_rgb_base_link"/>
  </joint>
  <link name="rb1_front_rgbd_camera_rgb_base_link">
    <inertial>
      <mass value="0.001"/>
      <origin xyz="0 0 0"/>
      <inertia ixx="0.0001" ixy="0.0" ixz="0.0" iyy="0.0001" iyz="0.0" izz="0.0001"/>
    </inertial>
  </link>
  <joint name="rb1_front_rgbd_camera_rgb_optical_joint" type="fixed">
    <origin rpy="-1.5707963267948966 0 -1.5707963267948966" xyz="0.0 0.0 0.0"/>
    <parent link="rb1_front_rgbd_camera_rgb_base_link"/>
    <child link="rb1_front_rgbd_camera_rgb_optical_frame"/>
  </joint>
  <link name="rb1_front_rgbd_camera_rgb_optical_frame">
    <inertial>
        <mass value="0.001" />
        <origin xyz="0 0 0" />
        <inertia ixx="0.0001" ixy="0.0" ixz="0.0"
          iyy="0.0001" iyz="0.0"
          izz="0.0001" />
      </inertial>
  </link>
  <joint name="rb1_front_rgbd_camera_joint" type="fixed">
    <origin rpy="0.0 0 0" xyz="0.0 -0.0125 -0.015"/>
    <parent link="rb1_front_rgbd_camera_rgb_base_link"/>
    <child link="rb1_front_rgbd_camera_link"/>
  </joint>
  <link name="rb1_front_rgbd_camera_link">
    <visual>
      <origin rpy="0 0 0" xyz="0 0 0"/>
      <geometry>
        <mesh filename="package://robotnik_sensors/meshes/orbbec_astra.dae" scale="1.0 1.0 1.0"/>
      </geometry>
    </visual>
    <collision>
      <origin rpy="0 0 0" xyz="0.0 0.0 0.0"/>
      <!--geometry>
        <box size="0.0730 .2760 0.0720"/>
      </geometry-->
      <geometry>
        <mesh filename="package://robotnik_sensors/meshes/orbbec_astra.dae" scale="1.0 1.0 1.0"/>
      </geometry>
    </collision>
    <inertial>
      <!--mass value="0.01" />
        <origin xyz="0 0 0" />
        <inertia ixx="0.001" ixy="0.0" ixz="0.0"
          iyy="0.001" iyz="0.0"
          izz="0.001" /-->
      <mass value="0.564"/>
      <origin xyz="0 0 0"/>
      <inertia ixx="0.003881243" ixy="0.0" ixz="0.0" iyy="0.000498940" iyz="0.0" izz="0.003879257"/>
    </inertial>
  </link>
  <joint name="rb1_front_rgbd_camera_depth_joint" type="fixed">
    <origin rpy="0 0 0" xyz="0.0 0.025 0.0"/>
    <parent link="rb1_front_rgbd_camera_rgb_base_link"/>
    <child link="rb1_front_rgbd_camera_depth_frame"/>
  </joint>
  <link name="rb1_front_rgbd_camera_depth_frame">
    <inertial>
        <mass value="0.01" />
        <origin xyz="0 0 0" />
        <inertia ixx="0.001" ixy="0.0" ixz="0.0"
          iyy="0.001" iyz="0.0"
          izz="0.001" />
      </inertial>
  </link>
  <joint name="rb1_front_rgbd_camera_depth_optical_joint" type="fixed">
    <origin rpy="-1.5707963267948966 0 -1.5707963267948966" xyz="0 0 0"/>
    <parent link="rb1_front_rgbd_camera_depth_frame"/>
    <child link="rb1_front_rgbd_camera_depth_optical_frame"/>
  </joint>
  <link name="rb1_front_rgbd_camera_depth_optical_frame">
    <inertial>
        <mass value="0.001" />
        <origin xyz="0 0 0" />
        <inertia ixx="0.0001" ixy="0.0" ixz="0.0"
          iyy="0.0001" iyz="0.0"
          izz="0.0001" />
      </inertial>
  </link>
  <!-- RGBD sensor for simulation, same as Kinect -->
  <sensor_orbbec_astra_gazebo/>
  <!-- TORSO & ARMS -->
  <link name="rb1_torso_link">
    <visual>
      <origin rpy="0 0 0" xyz="0 0 0"/>
      <geometry>
        <mesh filename="package://rb1_base_description/meshes/others/rb1_torso_ur3.stl"/>
      </geometry>
    </visual>
    <collision>
      <origin rpy="0 0 0" xyz="0 0 0"/>
      <geometry>
        <mesh filename="package://rb1_base_description/meshes/others/rb1_torso_ur3.stl"/>
      </geometry>
    </collision>
    <inertial>
      <mass value="4.0"/>
      <origin xyz="0 0 0"/>
      <inertia ixx="0.154375" ixy="0" ixz="0" iyy="0.154375" iyz="0" izz="0.005000000000000001"/>
    </inertial>
  </link>
  <joint name="rb1_torso_joint" type="fixed">
    <parent link="rb1_base_footprint"/>
    <child link="rb1_torso_link"/>
    <origin rpy="0.0 0.0 0.0" xyz="-0.1 0.0 0.248"/>
    <axis rpy="0 0 0" xyz="0 0 1"/>
  </joint>
  <link name="rb1_torso_ur3_right_link">
  <inertial>
      <mass value="0.01"/>
      <origin xyz="0 0 0"/>
      <inertia ixx="0.1" ixy="0.0" ixz="0.0" iyy="0.1" iyz="0.0" izz="0.1"/>
    </inertial>
    </link>
  <joint name="rb1_torso_ur3_right_joint" type="fixed">
    <parent link="rb1_torso_link"/>
    <child link="rb1_torso_ur3_right_link"/>
    <origin rpy="0 -2.356194490192345 1.5707963267948966" xyz="0.17 -0.1655 0.954"/>
  </joint>
  <link name="rb1_torso_ur3_left_link">
  <inertial>
      <mass value="0.01"/>
      <origin xyz="0 0 0"/>
      <inertia ixx="0.1" ixy="0.0" ixz="0.0" iyy="0.1" iyz="0.0" izz="0.1"/>
    </inertial>
    </link>
  <joint name="rb1_torso_ur3_left_joint" type="fixed">
    <parent link="rb1_torso_link"/>
    <child link="rb1_torso_ur3_left_link"/>
    <origin rpy="0 -2.356194490192345 -1.5707963267948966" xyz="0.17 0.1655 0.954"/>
  </joint>
  <!-- measured from model -->
  <link name="rb1_right_arm_base_link">
    <visual>
      <origin rpy="0 0 3.141592653589793" xyz="0 0 0"/>
      <geometry>
        <mesh filename="package://ur_description/meshes/ur3/visual/base.dae"/>
      </geometry>
      <material name="LightGrey">
        <color rgba="0.7 0.7 0.7 1.0"/>
      </material>
    </visual>
    <collision>
      <origin rpy="0 0 3.141592653589793" xyz="0 0 0"/>
      <geometry>
        <mesh filename="package://ur_description/meshes/ur3/collision/base.stl"/>
      </geometry>
    </collision>
    <inertial>
      <mass value="2.0"/>
      <origin rpy="0 0 0" xyz="0.0 0.0 0.0"/>
      <inertia ixx="0.0030531654454" ixy="0.0" ixz="0.0" iyy="0.0030531654454" iyz="0.0" izz="0.005625"/>
    </inertial>
  </link>
  <joint name="rb1_right_arm_shoulder_pan_joint" type="revolute">
    <parent link="rb1_right_arm_base_link"/>
    <child link="rb1_right_arm_shoulder_link"/>
    <origin rpy="0 0 3.141592653589793" xyz="0 0 0.1519"/>
    <axis xyz="0 0 1"/>
    <limit effort="330.0" lower="-6.283185307179586" upper="6.283185307179586" velocity="2.16"/>
    <dynamics damping="0.0" friction="0.0"/>
  </joint>
  <link name="rb1_right_arm_shoulder_link">
    <visual>
      <origin rpy="0 0 3.141592653589793" xyz="0 0 0"/>
      <geometry>
        <mesh filename="package://ur_description/meshes/ur3/visual/shoulder.dae"/>
      </geometry>
      <material name="LightGrey">
        <color rgba="0.7 0.7 0.7 1.0"/>
      </material>
    </visual>
    <collision>
      <origin rpy="0 0 3.141592653589793" xyz="0 0 0"/>
      <geometry>
        <mesh filename="package://ur_description/meshes/ur3/collision/shoulder.stl"/>
      </geometry>
    </collision>
    <inertial>
      <mass value="2.0"/>
      <origin rpy="0 0 0" xyz="0.0 0.0 0.0"/>
      <inertia ixx="0.008093163429399999" ixy="0.0" ixz="0.0" iyy="0.008093163429399999" iyz="0.0" izz="0.005625"/>
    </inertial>
  </link>
  <joint name="rb1_right_arm_shoulder_lift_joint" type="revolute">
    <parent link="rb1_right_arm_shoulder_link"/>
    <child link="rb1_right_arm_upper_arm_link"/>
    <origin rpy="1.570796327 0 0" xyz="0 0 0"/>
    <axis xyz="0 0 1"/>
    <limit effort="330.0" lower="-6.283185307179586" upper="6.283185307179586" velocity="2.16"/>
    <dynamics damping="0.0" friction="0.0"/>
  </joint>
  <link name="rb1_right_arm_upper_arm_link">
    <visual>
      <origin rpy="1.5707963267948966 0 -1.5707963267948966" xyz="0 0 0.1198"/>
      <geometry>
        <mesh filename="package://ur_description/meshes/ur3/visual/upperarm.dae"/>
      </geometry>
      <material name="LightGrey">
        <color rgba="0.7 0.7 0.7 1.0"/>
      </material>
    </visual>
    <collision>
      <origin rpy="1.5707963267948966 0 -1.5707963267948966" xyz="0 0 0.1198"/>
      <geometry>
        <mesh filename="package://ur_description/meshes/ur3/collision/upperarm.stl"/>
      </geometry>
    </collision>
    <inertial>
      <mass value="3.42"/>
      <origin rpy="0 1.5707963267948966 0" xyz="-0.121825 0.0 0.12"/>
      <inertia ixx="0.021728483221103233" ixy="0.0" ixz="0.0" iyy="0.021728483221103233" iyz="0.0" izz="0.00961875"/>
    </inertial>
  </link>
  <joint name="rb1_right_arm_elbow_joint" type="revolute">
    <parent link="rb1_right_arm_upper_arm_link"/>
    <child link="rb1_right_arm_forearm_link"/>
    <origin rpy="0 0 0" xyz="-0.24365 0 0"/>
    <axis xyz="0 0 1"/>
    <limit effort="150.0" lower="-6.283185307179586" upper="6.283185307179586" velocity="3.15"/>
    <dynamics damping="0.0" friction="0.0"/>
  </joint>
  <link name="rb1_right_arm_forearm_link">
    <visual>
      <origin rpy="1.5707963267948966 0 -1.5707963267948966" xyz="0 0 0.0275"/>
      <geometry>
        <mesh filename="package://ur_description/meshes/ur3/visual/forearm.dae"/>
      </geometry>
      <material name="LightGrey">
        <color rgba="0.7 0.7 0.7 1.0"/>
      </material>
    </visual>
    <collision>
      <origin rpy="1.5707963267948966 0 -1.5707963267948966" xyz="0 0 0.0275"/>
      <geometry>
        <mesh filename="package://ur_description/meshes/ur3/collision/forearm.stl"/>
      </geometry>
    </collision>
    <inertial>
      <mass value="1.26"/>
      <origin rpy="0 1.5707963267948966 0" xyz="-0.121825 0.0 0.0275"/>
      <inertia ixx="0.006546806443776375" ixy="0.0" ixz="0.0" iyy="0.006546806443776375" iyz="0.0" izz="0.00354375"/>
    </inertial>
  </link>
  <joint name="rb1_right_arm_wrist_1_joint" type="revolute">
    <parent link="rb1_right_arm_forearm_link"/>
    <child link="rb1_right_arm_wrist_1_link"/>
    <origin rpy="0 0 0" xyz="-0.21325 0 0.11235"/>
    <axis xyz="0 0 1"/>
    <limit effort="54.0" lower="-6.283185307179586" upper="6.283185307179586" velocity="3.2"/>
    <dynamics damping="0.0" friction="0.0"/>
  </joint>
  <link name="rb1_right_arm_wrist_1_link">
    <visual>
      <origin rpy="1.5707963267948966 0 0" xyz="0 0 -0.085"/>
      <geometry>
        <mesh filename="package://ur_description/meshes/ur3/visual/wrist1.dae"/>
      </geometry>
      <material name="LightGrey">
        <color rgba="0.7 0.7 0.7 1.0"/>
      </material>
    </visual>
    <collision>
      <origin rpy="1.5707963267948966 0 0" xyz="0 0 -0.085"/>
      <geometry>
        <mesh filename="package://ur_description/meshes/ur3/collision/wrist1.stl"/>
      </geometry>
    </collision>
    <inertial>
      <mass value="0.8"/>
      <origin rpy="0 0 0" xyz="0.0 0.0 0.0"/>
      <inertia ixx="0.0016106408557434" ixy="0.0" ixz="0.0" iyy="0.0016106408557434" iyz="0.0" izz="0.00225"/>
    </inertial>
  </link>
  <joint name="rb1_right_arm_wrist_2_joint" type="revolute">
    <parent link="rb1_right_arm_wrist_1_link"/>
    <child link="rb1_right_arm_wrist_2_link"/>
    <origin rpy="1.570796327 0 0" xyz="0 -0.08535 -1.750557762378351e-11"/>
    <axis xyz="0 0 1"/>
    <limit effort="54.0" lower="-6.283185307179586" upper="6.283185307179586" velocity="3.2"/>
    <dynamics damping="0.0" friction="0.0"/>
  </joint>
  <link name="rb1_right_arm_wrist_2_link">
    <visual>
      <origin rpy="0 0 0" xyz="0 0 -0.085"/>
      <geometry>
        <mesh filename="package://ur_description/meshes/ur3/visual/wrist2.dae"/>
      </geometry>
      <material name="LightGrey">
        <color rgba="0.7 0.7 0.7 1.0"/>
      </material>
    </visual>
    <collision>
      <origin rpy="0 0 0" xyz="0 0 -0.085"/>
      <geometry>
        <mesh filename="package://ur_description/meshes/ur3/collision/wrist2.stl"/>
      </geometry>
    </collision>
    <inertial>
      <mass value="0.8"/>
      <origin rpy="0 0 0" xyz="0.0 0.0 0.0"/>
      <inertia ixx="0.0015721733711303997" ixy="0.0" ixz="0.0" iyy="0.0015721733711303997" iyz="0.0" izz="0.00225"/>
    </inertial>
  </link>
  <joint name="rb1_right_arm_wrist_3_joint" type="revolute">
    <parent link="rb1_right_arm_wrist_2_link"/>
    <child link="rb1_right_arm_wrist_3_link"/>
    <origin rpy="1.570796326589793 3.141592653589793 3.141592653589793" xyz="0 0.0819 -1.679797079540562e-11"/>
    <axis xyz="0 0 1"/>
    <limit effort="54.0" lower="-6.283185307179586" upper="6.283185307179586" velocity="3.2"/>
    <dynamics damping="0.0" friction="0.0"/>
  </joint>
  <link name="rb1_right_arm_wrist_3_link">
    <visual>
      <origin rpy="1.5707963267948966 0 0" xyz="0 0 -0.082"/>
      <geometry>
        <mesh filename="package://ur_description/meshes/ur3/visual/wrist3.dae"/>
      </geometry>
      <material name="LightGrey">
        <color rgba="0.7 0.7 0.7 1.0"/>
      </material>
    </visual>
    <collision>
      <origin rpy="1.5707963267948966 0 0" xyz="0 0 -0.082"/>
      <geometry>
        <mesh filename="package://ur_description/meshes/ur3/collision/wrist3.stl"/>
      </geometry>
    </collision>
    <inertial>
      <mass value="0.35"/>
      <origin rpy="0 0 0" xyz="0.0 0.0 -0.01525"/>
      <inertia ixx="0.00020431970993874997" ixy="0.0" ixz="0.0" iyy="0.00020431970993874997" iyz="0.0" izz="0.000354375"/>
    </inertial>
  </link>
  <joint name="rb1_right_arm_ee_fixed_joint" type="fixed">
    <parent link="rb1_right_arm_wrist_3_link"/>
    <child link="rb1_right_arm_ee_link"/>
    <origin rpy="0.0 -1.5707963267948966 1.5707963267948966" xyz="0.0 0.0 0.0"/>
  </joint>
  <link name="rb1_right_arm_ee_link">
    <collision>
      <geometry>
        <box size="0.01 0.01 0.01"/>
      </geometry>
      <origin rpy="0 0 0" xyz="-0.01 0 0"/>
    </collision>
    <inertial>
      <mass value="0.1"/>
      <origin rpy="0 0 0" xyz="0.0 0.0 0.0"/>
      <inertia ixx="0.1" ixy="0.0" ixz="0.0" iyy="0.1" iyz="0.0" izz="0.1"/>
    </inertial>
  </link>
  <joint name="rb1_right_arm_wrist_3_passive_joint" type="fixed">
    <origin rpy="0 0 0" xyz="0 0 0"/>
    <parent link="rb1_right_arm_wrist_3_link"/>
    <child link="rb1_right_arm_tool0"/>
  </joint>
  <transmission name="rb1_right_arm_shoulder_pan_trans">
    <type>transmission_interface/SimpleTransmission</type>
    <joint name="rb1_right_arm_shoulder_pan_joint">
      <hardwareInterface>hardware_interface/PositionJointInterface</hardwareInterface>
    </joint>
    <actuator name="rb1_right_arm_shoulder_pan_motor">
      <mechanicalReduction>1</mechanicalReduction>
    </actuator>
  </transmission>
  <transmission name="rb1_right_arm_shoulder_lift_trans">
    <type>transmission_interface/SimpleTransmission</type>
    <joint name="rb1_right_arm_shoulder_lift_joint">
      <hardwareInterface>hardware_interface/PositionJointInterface</hardwareInterface>
    </joint>
    <actuator name="rb1_right_arm_shoulder_lift_motor">
      <mechanicalReduction>1</mechanicalReduction>
    </actuator>
  </transmission>
  <transmission name="rb1_right_arm_elbow_trans">
    <type>transmission_interface/SimpleTransmission</type>
    <joint name="rb1_right_arm_elbow_joint">
      <hardwareInterface>hardware_interface/PositionJointInterface</hardwareInterface>
    </joint>
    <actuator name="rb1_right_arm_elbow_motor">
      <mechanicalReduction>1</mechanicalReduction>
    </actuator>
  </transmission>
  <transmission name="rb1_right_arm_wrist_1_trans">
    <type>transmission_interface/SimpleTransmission</type>
    <joint name="rb1_right_arm_wrist_1_joint">
      <hardwareInterface>hardware_interface/PositionJointInterface</hardwareInterface>
    </joint>
    <actuator name="rb1_right_arm_wrist_1_motor">
      <mechanicalReduction>1</mechanicalReduction>
    </actuator>
  </transmission>
  <transmission name="rb1_right_arm_wrist_2_trans">
    <type>transmission_interface/SimpleTransmission</type>
    <joint name="rb1_right_arm_wrist_2_joint">
      <hardwareInterface>hardware_interface/PositionJointInterface</hardwareInterface>
    </joint>
    <actuator name="rb1_right_arm_wrist_2_motor">
      <mechanicalReduction>1</mechanicalReduction>
    </actuator>
  </transmission>
  <transmission name="rb1_right_arm_wrist_3_trans">
    <type>transmission_interface/SimpleTransmission</type>
    <joint name="rb1_right_arm_wrist_3_joint">
      <hardwareInterface>hardware_interface/PositionJointInterface</hardwareInterface>
    </joint>
    <actuator name="rb1_right_arm_wrist_3_motor">
      <mechanicalReduction>1</mechanicalReduction>
    </actuator>
  </transmission>
  <gazebo reference="rb1_right_arm_shoulder_link">
    <selfCollide>true</selfCollide>
  </gazebo>
  <gazebo reference="rb1_right_arm_upper_arm_link">
    <selfCollide>true</selfCollide>
  </gazebo>
  <gazebo reference="rb1_right_arm_forearm_link">
    <selfCollide>true</selfCollide>
  </gazebo>
  <gazebo reference="rb1_right_arm_wrist_1_link">
    <selfCollide>true</selfCollide>
  </gazebo>
  <gazebo reference="rb1_right_arm_wrist_3_link">
    <selfCollide>true</selfCollide>
  </gazebo>
  <gazebo reference="rb1_right_arm_wrist_2_link">
    <selfCollide>true</selfCollide>
  </gazebo>
  <gazebo reference="rb1_right_arm_ee_link">
    <selfCollide>true</selfCollide>
  </gazebo>
  <!-- ROS base_link to UR 'Base' Coordinates transform -->
  <link name="rb1_right_arm_base">
  <inertial>
      <mass value="0.0"/>
      <origin rpy="0 0 0" xyz="0.0 0.0 0.0"/>
      <inertia ixx="0.0" ixy="0.0" ixz="0.0" iyy="0.0" iyz="0.0" izz="0.0"/>
    </inertial>
  </link>
  <joint name="rb1_right_arm_base_link-base_fixed_joint" type="fixed">
    <!-- NOTE: this rotation is only needed as long as base_link itself is
                 not corrected wrt the real robot (ie: rotated over 180
                 degrees)
      -->
    <origin rpy="0 0 -3.141592653589793" xyz="0 0 0"/>
    <parent link="rb1_right_arm_base_link"/>
    <child link="rb1_right_arm_base"/>
  </joint>
  <!-- Frame coincident with all-zeros TCP on UR controller -->
  <link name="rb1_right_arm_tool0">
  <inertial>
      <mass value="0.1"/>
      <origin rpy="0 0 0" xyz="0.0 0.0 0.0"/>
      <inertia ixx="0.1" ixy="0.0" ixz="0.0" iyy="0.1" iyz="0.0" izz="0.1"/>
  </inertial>
  </link>
  <joint name="rb1_right_arm_base_joint" type="fixed">
    <origin rpy="0.0 0.0 0.0" xyz="0.0 0.0 0.0"/>
    <parent link="rb1_torso_ur3_right_link"/>
    <child link="rb1_right_arm_base_link"/>
  </joint>
  <!-- measured from model -->
  <link name="rb1_left_arm_base_link">
    <visual>
      <origin rpy="0 0 3.141592653589793" xyz="0 0 0"/>
      <geometry>
        <mesh filename="package://ur_description/meshes/ur3/visual/base.dae"/>
      </geometry>
      <material name="LightGrey">
        <color rgba="0.7 0.7 0.7 1.0"/>
      </material>
    </visual>
    <collision>
      <origin rpy="0 0 3.141592653589793" xyz="0 0 0"/>
      <geometry>
        <mesh filename="package://ur_description/meshes/ur3/collision/base.stl"/>
      </geometry>
    </collision>
    <inertial>
      <mass value="2.0"/>
      <origin rpy="0 0 0" xyz="0.0 0.0 0.0"/>
      <inertia ixx="0.0030531654454" ixy="0.0" ixz="0.0" iyy="0.0030531654454" iyz="0.0" izz="0.005625"/>
    </inertial>
  </link>
  <joint name="rb1_left_arm_shoulder_pan_joint" type="revolute">
    <parent link="rb1_left_arm_base_link"/>
    <child link="rb1_left_arm_shoulder_link"/>
    <origin rpy="0 0 3.141592653589793" xyz="0 0 0.1519"/>
    <axis xyz="0 0 1"/>
    <limit effort="330.0" lower="-6.283185307179586" upper="6.283185307179586" velocity="2.16"/>
    <dynamics damping="0.0" friction="0.0"/>
  </joint>
  <link name="rb1_left_arm_shoulder_link">
    <visual>
      <origin rpy="0 0 3.141592653589793" xyz="0 0 0"/>
      <geometry>
        <mesh filename="package://ur_description/meshes/ur3/visual/shoulder.dae"/>
      </geometry>
      <material name="LightGrey">
        <color rgba="0.7 0.7 0.7 1.0"/>
      </material>
    </visual>
    <collision>
      <origin rpy="0 0 3.141592653589793" xyz="0 0 0"/>
      <geometry>
        <mesh filename="package://ur_description/meshes/ur3/collision/shoulder.stl"/>
      </geometry>
    </collision>
    <inertial>
      <mass value="2.0"/>
      <origin rpy="0 0 0" xyz="0.0 0.0 0.0"/>
      <inertia ixx="0.008093163429399999" ixy="0.0" ixz="0.0" iyy="0.008093163429399999" iyz="0.0" izz="0.005625"/>
    </inertial>
  </link>
  <joint name="rb1_left_arm_shoulder_lift_joint" type="revolute">
    <parent link="rb1_left_arm_shoulder_link"/>
    <child link="rb1_left_arm_upper_arm_link"/>
    <origin rpy="1.570796327 0 0" xyz="0 0 0"/>
    <axis xyz="0 0 1"/>
    <limit effort="330.0" lower="-6.283185307179586" upper="6.283185307179586" velocity="2.16"/>
    <dynamics damping="0.0" friction="0.0"/>
  </joint>
  <link name="rb1_left_arm_upper_arm_link">
    <visual>
      <origin rpy="1.5707963267948966 0 -1.5707963267948966" xyz="0 0 0.1198"/>
      <geometry>
        <mesh filename="package://ur_description/meshes/ur3/visual/upperarm.dae"/>
      </geometry>
      <material name="LightGrey">
        <color rgba="0.7 0.7 0.7 1.0"/>
      </material>
    </visual>
    <collision>
      <origin rpy="1.5707963267948966 0 -1.5707963267948966" xyz="0 0 0.1198"/>
      <geometry>
        <mesh filename="package://ur_description/meshes/ur3/collision/upperarm.stl"/>
      </geometry>
    </collision>
    <inertial>
      <mass value="3.42"/>
      <origin rpy="0 1.5707963267948966 0" xyz="-0.121825 0.0 0.12"/>
      <inertia ixx="0.021728483221103233" ixy="0.0" ixz="0.0" iyy="0.021728483221103233" iyz="0.0" izz="0.00961875"/>
    </inertial>
  </link>
  <joint name="rb1_left_arm_elbow_joint" type="revolute">
    <parent link="rb1_left_arm_upper_arm_link"/>
    <child link="rb1_left_arm_forearm_link"/>
    <origin rpy="0 0 0" xyz="-0.24365 0 0"/>
    <axis xyz="0 0 1"/>
    <limit effort="150.0" lower="-6.283185307179586" upper="6.283185307179586" velocity="3.15"/>
    <dynamics damping="0.0" friction="0.0"/>
  </joint>
  <link name="rb1_left_arm_forearm_link">
    <visual>
      <origin rpy="1.5707963267948966 0 -1.5707963267948966" xyz="0 0 0.0275"/>
      <geometry>
        <mesh filename="package://ur_description/meshes/ur3/visual/forearm.dae"/>
      </geometry>
      <material name="LightGrey">
        <color rgba="0.7 0.7 0.7 1.0"/>
      </material>
    </visual>
    <collision>
      <origin rpy="1.5707963267948966 0 -1.5707963267948966" xyz="0 0 0.0275"/>
      <geometry>
        <mesh filename="package://ur_description/meshes/ur3/collision/forearm.stl"/>
      </geometry>
    </collision>
    <inertial>
      <mass value="1.26"/>
      <origin rpy="0 1.5707963267948966 0" xyz="-0.121825 0.0 0.0275"/>
      <inertia ixx="0.006546806443776375" ixy="0.0" ixz="0.0" iyy="0.006546806443776375" iyz="0.0" izz="0.00354375"/>
    </inertial>
  </link>
  <joint name="rb1_left_arm_wrist_1_joint" type="revolute">
    <parent link="rb1_left_arm_forearm_link"/>
    <child link="rb1_left_arm_wrist_1_link"/>
    <origin rpy="0 0 0" xyz="-0.21325 0 0.11235"/>
    <axis xyz="0 0 1"/>
    <limit effort="54.0" lower="-6.283185307179586" upper="6.283185307179586" velocity="3.2"/>
    <dynamics damping="0.0" friction="0.0"/>
  </joint>
  <link name="rb1_left_arm_wrist_1_link">
    <visual>
      <origin rpy="1.5707963267948966 0 0" xyz="0 0 -0.085"/>
      <geometry>
        <mesh filename="package://ur_description/meshes/ur3/visual/wrist1.dae"/>
      </geometry>
      <material name="LightGrey">
        <color rgba="0.7 0.7 0.7 1.0"/>
      </material>
    </visual>
    <collision>
      <origin rpy="1.5707963267948966 0 0" xyz="0 0 -0.085"/>
      <geometry>
        <mesh filename="package://ur_description/meshes/ur3/collision/wrist1.stl"/>
      </geometry>
    </collision>
    <inertial>
      <mass value="0.8"/>
      <origin rpy="0 0 0" xyz="0.0 0.0 0.0"/>
      <inertia ixx="0.0016106408557434" ixy="0.0" ixz="0.0" iyy="0.0016106408557434" iyz="0.0" izz="0.00225"/>
    </inertial>
  </link>
  <joint name="rb1_left_arm_wrist_2_joint" type="revolute">
    <parent link="rb1_left_arm_wrist_1_link"/>
    <child link="rb1_left_arm_wrist_2_link"/>
    <origin rpy="1.570796327 0 0" xyz="0 -0.08535 -1.750557762378351e-11"/>
    <axis xyz="0 0 1"/>
    <limit effort="54.0" lower="-6.283185307179586" upper="6.283185307179586" velocity="3.2"/>
    <dynamics damping="0.0" friction="0.0"/>
  </joint>
  <link name="rb1_left_arm_wrist_2_link">
    <visual>
      <origin rpy="0 0 0" xyz="0 0 -0.085"/>
      <geometry>
        <mesh filename="package://ur_description/meshes/ur3/visual/wrist2.dae"/>
      </geometry>
      <material name="LightGrey">
        <color rgba="0.7 0.7 0.7 1.0"/>
      </material>
    </visual>
    <collision>
      <origin rpy="0 0 0" xyz="0 0 -0.085"/>
      <geometry>
        <mesh filename="package://ur_description/meshes/ur3/collision/wrist2.stl"/>
      </geometry>
    </collision>
    <inertial>
      <mass value="0.8"/>
      <origin rpy="0 0 0" xyz="0.0 0.0 0.0"/>
      <inertia ixx="0.0015721733711303997" ixy="0.0" ixz="0.0" iyy="0.0015721733711303997" iyz="0.0" izz="0.00225"/>
    </inertial>
  </link>
  <joint name="rb1_left_arm_wrist_3_joint" type="revolute">
    <parent link="rb1_left_arm_wrist_2_link"/>
    <child link="rb1_left_arm_wrist_3_link"/>
    <origin rpy="1.570796326589793 3.141592653589793 3.141592653589793" xyz="0 0.0819 -1.679797079540562e-11"/>
    <axis xyz="0 0 1"/>
    <limit effort="54.0" lower="-6.283185307179586" upper="6.283185307179586" velocity="3.2"/>
    <dynamics damping="0.0" friction="0.0"/>
  </joint>
  <link name="rb1_left_arm_wrist_3_link">
    <visual>
      <origin rpy="1.5707963267948966 0 0" xyz="0 0 -0.082"/>
      <geometry>
        <mesh filename="package://ur_description/meshes/ur3/visual/wrist3.dae"/>
      </geometry>
      <material name="LightGrey">
        <color rgba="0.7 0.7 0.7 1.0"/>
      </material>
    </visual>
    <collision>
      <origin rpy="1.5707963267948966 0 0" xyz="0 0 -0.082"/>
      <geometry>
        <mesh filename="package://ur_description/meshes/ur3/collision/wrist3.stl"/>
      </geometry>
    </collision>
    <inertial>
      <mass value="0.35"/>
      <origin rpy="0 0 0" xyz="0.0 0.0 -0.01525"/>
      <inertia ixx="0.00020431970993874997" ixy="0.0" ixz="0.0" iyy="0.00020431970993874997" iyz="0.0" izz="0.000354375"/>
    </inertial>
  </link>
  <joint name="rb1_left_arm_ee_fixed_joint" type="fixed">
    <parent link="rb1_left_arm_wrist_3_link"/>
    <child link="rb1_left_arm_ee_link"/>
    <origin rpy="0.0 -1.5707963267948966 1.5707963267948966" xyz="0.0 0.0 0.0"/>
  </joint>
  <link name="rb1_left_arm_ee_link">
    <collision>
      <geometry>
        <box size="0.01 0.01 0.01"/>
      </geometry>
      <origin rpy="0 0 0" xyz="-0.01 0 0"/>
    </collision>
    <inertial>
      <mass value="0.0"/>
      <origin rpy="0 0 0" xyz="0.0 0.0 0.0"/>
      <inertia ixx="0.00000" ixy="0.0" ixz="0.0" iyy="0.00000" iyz="0.0" izz="0.000000"/>
    </inertial>
  </link>
  <joint name="rb1_left_arm_wrist_3_passive_joint" type="fixed">
    <origin rpy="0 0 0" xyz="0 0 0"/>
    <parent link="rb1_left_arm_wrist_3_link"/>
    <child link="rb1_left_arm_tool0"/>
  </joint>
  <transmission name="rb1_left_arm_shoulder_pan_trans">
    <type>transmission_interface/SimpleTransmission</type>
    <joint name="rb1_left_arm_shoulder_pan_joint">
      <hardwareInterface>hardware_interface/PositionJointInterface</hardwareInterface>
    </joint>
    <actuator name="rb1_left_arm_shoulder_pan_motor">
      <mechanicalReduction>1</mechanicalReduction>
    </actuator>
  </transmission>
  <transmission name="rb1_left_arm_shoulder_lift_trans">
    <type>transmission_interface/SimpleTransmission</type>
    <joint name="rb1_left_arm_shoulder_lift_joint">
      <hardwareInterface>hardware_interface/PositionJointInterface</hardwareInterface>
    </joint>
    <actuator name="rb1_left_arm_shoulder_lift_motor">
      <mechanicalReduction>1</mechanicalReduction>
    </actuator>
  </transmission>
  <transmission name="rb1_left_arm_elbow_trans">
    <type>transmission_interface/SimpleTransmission</type>
    <joint name="rb1_left_arm_elbow_joint">
      <hardwareInterface>hardware_interface/PositionJointInterface</hardwareInterface>
    </joint>
    <actuator name="rb1_left_arm_elbow_motor">
      <mechanicalReduction>1</mechanicalReduction>
    </actuator>
  </transmission>
  <transmission name="rb1_left_arm_wrist_1_trans">
    <type>transmission_interface/SimpleTransmission</type>
    <joint name="rb1_left_arm_wrist_1_joint">
      <hardwareInterface>hardware_interface/PositionJointInterface</hardwareInterface>
    </joint>
    <actuator name="rb1_left_arm_wrist_1_motor">
      <mechanicalReduction>1</mechanicalReduction>
    </actuator>
  </transmission>
  <transmission name="rb1_left_arm_wrist_2_trans">
    <type>transmission_interface/SimpleTransmission</type>
    <joint name="rb1_left_arm_wrist_2_joint">
      <hardwareInterface>hardware_interface/PositionJointInterface</hardwareInterface>
    </joint>
    <actuator name="rb1_left_arm_wrist_2_motor">
      <mechanicalReduction>1</mechanicalReduction>
    </actuator>
  </transmission>
  <transmission name="rb1_left_arm_wrist_3_trans">
    <type>transmission_interface/SimpleTransmission</type>
    <joint name="rb1_left_arm_wrist_3_joint">
      <hardwareInterface>hardware_interface/PositionJointInterface</hardwareInterface>
    </joint>
    <actuator name="rb1_left_arm_wrist_3_motor">
      <mechanicalReduction>1</mechanicalReduction>
    </actuator>
  </transmission>
  <gazebo reference="rb1_left_arm_shoulder_link">
    <selfCollide>true</selfCollide>
  </gazebo>
  <gazebo reference="rb1_left_arm_upper_arm_link">
    <selfCollide>true</selfCollide>
  </gazebo>
  <gazebo reference="rb1_left_arm_forearm_link">
    <selfCollide>true</selfCollide>
  </gazebo>
  <gazebo reference="rb1_left_arm_wrist_1_link">
    <selfCollide>true</selfCollide>
  </gazebo>
  <gazebo reference="rb1_left_arm_wrist_3_link">
    <selfCollide>true</selfCollide>
  </gazebo>
  <gazebo reference="rb1_left_arm_wrist_2_link">
    <selfCollide>true</selfCollide>
  </gazebo>
  <gazebo reference="rb1_left_arm_ee_link">
    <selfCollide>true</selfCollide>
  </gazebo>
  <!-- ROS base_link to UR 'Base' Coordinates transform -->
  <link name="rb1_left_arm_base">
  <inertial>
      <mass value="0.0"/>
      <origin rpy="0 0 0" xyz="0.0 0.0 0.0"/>
      <inertia ixx="0.0" ixy="0.0" ixz="0.0" iyy="0.0" iyz="0.0" izz="0.0"/>
    </inertial>
  </link>
  <joint name="rb1_left_arm_base_link-base_fixed_joint" type="fixed">
    <!-- NOTE: this rotation is only needed as long as base_link itself is
                 not corrected wrt the real robot (ie: rotated over 180
                 degrees)
      -->
    <origin rpy="0 0 -3.141592653589793" xyz="0 0 0"/>
    <parent link="rb1_left_arm_base_link"/>
    <child link="rb1_left_arm_base"/>
  </joint>
  <!-- Frame coincident with all-zeros TCP on UR controller -->
  <link name="rb1_left_arm_tool0">
  <inertial>
      <mass value="0.00"/>
      <origin rpy="0 0 0" xyz="0.0 0.0 0.0"/>
      <inertia ixx="0.0" ixy="0.0" ixz="0.0" iyy="0.0" iyz="0.0" izz="0.0"/>
    </inertial>
  </link>
  <joint name="rb1_left_arm_base_joint" type="fixed">
    <origin rpy="0.0 0.0 0.0" xyz="0.0 0.0 0.0"/>
    <parent link="rb1_torso_ur3_left_link"/>
    <child link="rb1_left_arm_base_link"/>
  </joint>
  <!--link name="world"/-->


</robot>
