<?xml version="1.0" ?>
<!-- =================================================================================== -->
<!-- |    This document was autogenerated by xacro from rb1_dual_ur3.urdf.xacro        | -->
<!-- |    EDITING THIS FILE BY HAND IS NOT RECOMMENDED                                 | -->
<!-- =================================================================================== -->
<robot name="rb1_base">
  <!-- ***************** -->
  <!-- Imported elements -->
  <!-- ***************** -->
  <!-- First we import all posible elements defined in the urdf.xacro files. All these elements are defined as macro:xacros -->
  <!-- v3 name from engineering department -->
  <!--
  Author: Felix Messmer
-->
  <!-- in kg-->
  <!-- in kg-->
  <!-- This file unifies all sensors that can be used on simulation, defined as xacro:macros -->
  <!-- Includes -->
  <!-- *************** -->
  <!-- Robots Elements -->
  <!-- *************** -->
  <!-- Here we create the robot elements using the xacro:macros imported at the beggining of this file -->
  <link name="rb1_base_footprint">
    <inertial>
      <mass value="1.0"/>
      <origin rpy="0 0 0" xyz="0 0 0"/>
      <inertia ixx="0.01" ixy="0.0" ixz="0.0" iyy="0.01" iyz="0.0" izz="0.01"/>
    </inertial>
    <visual>
      <origin rpy="0 0 0" xyz="0 0 0"/>
      <geometry>
        <box size="0.001 0.001 0.001"/>
      </geometry>
    </visual>
  </link>
  <!-- BASE_LINK -->
  <link name="rb1_base_link">
    <inertial>
      <mass value="25.0"/>
      <origin xyz="0 0 0"/>
      <inertia ixx="0.605" ixy="0.0" ixz="0.0" iyy="0.5435" iyz="0.0" izz="0.981"/>
    </inertial>
    <visual>
      <origin rpy="0 0 0" xyz="0 0 0"/>
      <geometry>
        <mesh filename="package://rb1_base_description/meshes/bases/rb1_base_v3.stl"/>
      </geometry>
      <material name="darkgrey">
        <color rgba="0.1 0.1 0.1 1"/>
      </material>
    </visual>
    <!--collision>
        <origin xyz="0 0 0" rpy="0 0 0 " />
        <geometry>
          <mesh filename="package://rb1_base_description/meshes/bases/rb1_base_v3.dae"/>
        </geometry>
      </collision-->
  </link>
  <joint name="rb1_base_footprint_joint" type="fixed">
    <origin rpy="0 0 0" xyz="0 0 0.024799999999999996"/>
    <parent link="rb1_base_footprint"/>
    <child link="rb1_base_link"/>
  </joint>
  <!-- FRONT COVER -->
  <link name="rb1_front_cover_link">
    <inertial>
      <mass value="0.25"/>
      <origin xyz="0 0 0"/>
      <inertia ixx="0.00007" ixy="0.0" ixz="0.0" iyy="0.00007" iyz="0.0" izz="0.0078"/>
    </inertial>
    <visual>
      <origin rpy="0 0 0" xyz="0 0 0"/>
      <geometry>
        <mesh filename="package://rb1_base_description/meshes/bases/rb1_front_cover_v3.stl"/>
      </geometry>
      <material name="black">
        <color rgba="0.0 0.0 0.0 1"/>
      </material>
    </visual>
    <collision>
      <origin rpy="0 0 0 " xyz="0 0 0"/>
      <geometry>
        <mesh filename="package://rb1_base_description/meshes/bases/rb1_front_cover_v3.dae"/>
      </geometry>
    </collision>
  </link>
  <joint name="rb1_front_cover_joint" type="fixed">
    <origin rpy="0 0 0 " xyz="0.220 0.0 0.004"/>
    <parent link="rb1_base_link"/>
    <child link="rb1_front_cover_link"/>
  </joint>
  <!-- FRONT COVER -->
  <link name="rb1_top_cover_link">
    <inertial>
      <mass value="0.25"/>
      <origin xyz="0 0 0"/>
      <inertia ixx="0.00007" ixy="0.0" ixz="0.0" iyy="0.00007" iyz="0.0" izz="0.0078"/>
    </inertial>
    <visual>
      <origin rpy="0 0 0" xyz="0 0 0"/>
      <geometry>
        <mesh filename="package://rb1_base_description/meshes/bases/rb1_top_cover_v3.stl"/>
      </geometry>
      <material name="black">
        <color rgba="0.0 0.0 0.0 1"/>
      </material>
    </visual>
    <collision>
      <origin rpy="0 0 0 " xyz="0 0 0"/>
      <geometry>
        <mesh filename="package://rb1_base_description/meshes/bases/rb1_top_cover_v3.dae"/>
      </geometry>
    </collision>
  </link>
  <joint name="rb1_top_covert_joint" type="fixed">
    <origin rpy="0 0 0 " xyz="0.0 0.0 0.243"/>
    <parent link="rb1_base_footprint"/>
    <child link="rb1_top_cover_link"/>
  </joint>
  <!-- DOCKING LINK -->
  <link name="rb1_base_docking_contact_link">
    <inertial>
      <mass value="0.1"/>
      <origin rpy="0 0 0" xyz="0 0 0"/>
      <inertia ixx="0.001" ixy="0.0" ixz="0.0" iyy="0.001" iyz="0.0" izz="0.001"/>
    </inertial>
  </link>
  <!-- DOCKING CONTACTS -->
  <joint name="rb1_base_docking_joint" type="fixed">
    <origin rpy="0 0 0 " xyz="0.030 0.000 0.068"/>
    <parent link="rb1_front_cover_link"/>
    <child link="rb1_base_docking_contact_link"/>
  </joint>
  <gazebo>
    <plugin filename="libgazebo_ros_control.so" name="ros_control">
      <!--robotNamespace>/rb1</robotNamespace-->
      <robotParam>robot_description</robotParam>
      <controlPeriod>0.001</controlPeriod>
      <robotSimType>gazebo_ros_control/DefaultRobotHWSim</robotSimType>
      <legacyModeNS>true</legacyModeNS>
    </plugin>
  </gazebo>
  <gazebo reference="rb1_base_footprint">
    <material>Gazebo/Green</material>
  </gazebo>
  <gazebo reference="rb1_base_link">
    <material>Gazebo/Black</material>
  </gazebo>
  <gazebo reference="rb1_front_cover_link">
    <material>Gazebo/Black</material>
  </gazebo>
  <!--WHEEL TIRE -->
  <link name="rb1_right_wheel_link">
    <visual>
      <origin rpy="0 0 0" xyz="0 0 0"/>
      <geometry>
        <mesh filename="package://rb1_base_description/meshes/wheels/wheel_rubber_6inch.dae"/>
      </geometry>
    </visual>
    <collision>
      <origin rpy="1.5707963267948966 0 0" xyz="0 0 0"/>
      <geometry>
        <cylinder length="0.025" radius="0.076"/>
      </geometry>
    </collision>
    <inertial>
      <mass value="1.0"/>
      <origin rpy="1.5707963267948966 0 0" xyz="0 0 0"/>
      <inertia ixx="0.0014960833333333334" ixy="0" ixz="0" iyy="0.0014960833333333334" iyz="0" izz="0.002888"/>
    </inertial>
  </link>
  <joint name="rb1_right_wheel_joint" type="continuous">
    <parent link="rb1_base_link"/>
    <child link="rb1_right_wheel_link"/>
    <origin rpy="0 0 0" xyz="0.0 -0.218 0.0512"/>
    <axis rpy="0 0 0" xyz="0 1 0"/>
    <limit effort="100" velocity="100"/>
    <joint_properties damping="0.0" friction="0.0"/>
  </joint>
  <!-- Transmission is important to link the joints and the controller (see rb1_control/config/rb1_control.yaml)-->
  <transmission name="rb1_right_wheel_joint_trans">
    <type>transmission_interface/SimpleTransmission</type>
    <joint name="rb1_right_wheel_joint">
      <!-- for the gazebo plugin -->
      <!--hardwareInterface>EffortJointInterface</hardwareInterface-->
      <!-- for ros control controller -->
      <hardwareInterface>hardware_interface/VelocityJointInterface</hardwareInterface>
    </joint>
    <actuator name="rb1_right_wheel_joint_motor">
      <mechanicalReduction>1</mechanicalReduction>
      <motorTorqueConstant>20</motorTorqueConstant>
    </actuator>
  </transmission>
  <gazebo reference="rb1_right_wheel_link">
    <mu1 value="5.0"/>
    <mu2 value="0.5"/>
    <kp value="10000000.0"/>
    <kd value="1.0"/>
    <fdir1 value="1 0 0"/>
    <material>Gazebo/Yellow</material>
    <turnGravityOff>false</turnGravityOff>
    <!--kp>500000.0</kp>
			<kd>10.0</kd>
			<mu1>10</mu1>
			<mu2>10</mu2>
			<fdir1>1 0 0</fdir1-->
    <!--minDepth>0.001</minDepth-->
    <!--material>Gazebo/Black</material-->
    <!--mu1 value="10"/>
			<mu2 value="5"/>
			<kp value="500000.0" />
			<kd value="10.0" />
			<fdir1 value="1 0 0"/>
			<material>Gazebo/Yellow</material>
			<turnGravityOff>false</turnGravityOff-->
  </gazebo>
  <!--gazebo reference="${name}_wheel_link">
			<kp>500000.0</kp>
			<kd>10.0</kd>
			<mu1>10</mu1>
			<mu2>10</mu2>
			<fdir1>1 0 0</fdir1>
			<maxVel>1.0</maxVel>
			<minDepth>0.003</minDepth>
			<material>Gazebo/Yellow</material>
			<turnGravityOff>false</turnGravityOff>
			<implicitSpringDamper>1</implicitSpringDamper>
		</gazebo-->
  <!--WHEEL TIRE -->
  <link name="rb1_left_wheel_link">
    <visual>
      <origin rpy="0 0 0" xyz="0 0 0"/>
      <geometry>
        <mesh filename="package://rb1_base_description/meshes/wheels/wheel_rubber_6inch.dae"/>
      </geometry>
    </visual>
    <collision>
      <origin rpy="1.5707963267948966 0 0" xyz="0 0 0"/>
      <geometry>
        <cylinder length="0.025" radius="0.076"/>
      </geometry>
    </collision>
    <inertial>
      <mass value="1.0"/>
      <origin rpy="1.5707963267948966 0 0" xyz="0 0 0"/>
      <inertia ixx="0.0014960833333333334" ixy="0" ixz="0" iyy="0.0014960833333333334" iyz="0" izz="0.002888"/>
    </inertial>
  </link>
  <joint name="rb1_left_wheel_joint" type="continuous">
    <parent link="rb1_base_link"/>
    <child link="rb1_left_wheel_link"/>
    <origin rpy="0 0 0" xyz="0.0 0.218 0.0512"/>
    <axis rpy="0 0 0" xyz="0 1 0"/>
    <limit effort="100" velocity="100"/>
    <joint_properties damping="0.0" friction="0.0"/>
  </joint>
  <!-- Transmission is important to link the joints and the controller (see rb1_control/config/rb1_control.yaml)-->
  <transmission name="rb1_left_wheel_joint_trans">
    <type>transmission_interface/SimpleTransmission</type>
    <joint name="rb1_left_wheel_joint">
      <!-- for the gazebo plugin -->
      <!--hardwareInterface>EffortJointInterface</hardwareInterface-->
      <!-- for ros control controller -->
      <hardwareInterface>hardware_interface/VelocityJointInterface</hardwareInterface>
    </joint>
    <actuator name="rb1_left_wheel_joint_motor">
      <mechanicalReduction>1</mechanicalReduction>
      <motorTorqueConstant>20</motorTorqueConstant>
    </actuator>
  </transmission>
  <gazebo reference="rb1_left_wheel_link">
    <mu1 value="5.0"/>
    <mu2 value="0.5"/>
    <kp value="10000000.0"/>
    <kd value="1.0"/>
    <fdir1 value="1 0 0"/>
    <material>Gazebo/Yellow</material>
    <turnGravityOff>false</turnGravityOff>
    <!--kp>500000.0</kp>
			<kd>10.0</kd>
			<mu1>10</mu1>
			<mu2>10</mu2>
			<fdir1>1 0 0</fdir1-->
    <!--minDepth>0.001</minDepth-->
    <!--material>Gazebo/Black</material-->
    <!--mu1 value="10"/>
			<mu2 value="5"/>
			<kp value="500000.0" />
			<kd value="10.0" />
			<fdir1 value="1 0 0"/>
			<material>Gazebo/Yellow</material>
			<turnGravityOff>false</turnGravityOff-->
  </gazebo>
  <!--gazebo reference="${name}_wheel_link">
			<kp>500000.0</kp>
			<kd>10.0</kd>
			<mu1>10</mu1>
			<mu2>10</mu2>
			<fdir1>1 0 0</fdir1>
			<maxVel>1.0</maxVel>
			<minDepth>0.003</minDepth>
			<material>Gazebo/Yellow</material>
			<turnGravityOff>false</turnGravityOff>
			<implicitSpringDamper>1</implicitSpringDamper>
		</gazebo-->
  <!--WHEEL TIRE -->
  <link name="rb1_omni_backwheel_link">
    <visual>
      <origin rpy="0 0 0" xyz="0 0 0"/>
      <geometry>
        <mesh filename="package://rb1_base_description/meshes/wheels/rb1v2_omniwheel.dae"/>
      </geometry>
    </visual>
    <collision>
      <origin rpy="1.5707963267948966 0 0" xyz="0 0 0"/>
      <geometry>
        <cylinder length="0.03" radius="0.051"/>
      </geometry>
    </collision>
    <!--collision>
      <origin xyz="0 0 0" rpy="${M_PI/2} 0 0" />
       <geometry>
         <sphere radius="${omni_wheel_radius}"/>
       </geometry>
     </collision-->
    <inertial>
      <mass value="1.0"/>
      <origin xyz="0 0 0"/>
      <inertia ixx="0.00023507499999999998" ixy="0" ixz="0" iyy="0.00023507499999999998" iyz="0" izz="0.0003901499999999999"/>
      <!-- inertia  ixx="0.001" ixy="0.0"  ixz="0.0"  iyy="0.001"  iyz="0.0"  izz="0.001" / -->
    </inertial>
  </link>
  <!-- joint name="joint_${name}_wheel" type="continuous" -->
  <joint name="rb1_omni_backwheel_joint" type="fixed">
    <parent link="rb1_base_link"/>
    <child link="rb1_omni_backwheel_link"/>
    <origin rpy="0 0 0" xyz="-0.195 0.0 0.027"/>
    <axis rpy="0 0 0" xyz="0 1 0"/>
    <limit effort="100" velocity="100"/>
    <joint_properties damping="0.0" friction="0.0"/>
  </joint>
  <!-- transmission name="${name}_wheel_joint_trans">
      <type>transmission_interface/SimpleTransmission</type>
      <joint name="joint_${name}_wheel" />
      <actuator name="${name}_wheel_joint_motor">
        <hardwareInterface>EffortJointInterface</hardwareInterface>
        <mechanicalReduction>1</mechanicalReduction>
      </actuator>
    </transmission -->
  <gazebo reference="rb1_omni_backwheel">
    <mu1 value="0"/>
    <mu2 value="0"/>
    <kp value="10000000.0"/>
    <kd value="1.0"/>
    <fdir1 value="1 0 0"/>
    <material>Gazebo/Black</material>
    <turnGravityOff>false</turnGravityOff>
  </gazebo>
  <!--gazebo reference="${name}_wheel">
		<kp>500000.0</kp>
		<kd>10.0</kd>
		<mu1>10</mu1>
		<mu2>10</mu2>
		<fdir1>1 0 0</fdir1>
		<maxVel>1.0</maxVel>
		<minDepth>0.003</minDepth>
		<material>Gazebo/Black</material>
		<turnGravityOff>false</turnGravityOff>
		<implicitSpringDamper>1</implicitSpringDamper>
    </gazebo-->
  <!--WHEEL TIRE -->
  <link name="rb1_omni_front_leftwheel_link">
    <visual>
      <origin rpy="0 0 0" xyz="0 0 0"/>
      <geometry>
        <mesh filename="package://rb1_base_description/meshes/wheels/rb1v2_omniwheel.dae"/>
      </geometry>
    </visual>
    <collision>
      <origin rpy="1.5707963267948966 0 0" xyz="0 0 0"/>
      <geometry>
        <cylinder length="0.03" radius="0.051"/>
      </geometry>
    </collision>
    <!--collision>
      <origin xyz="0 0 0" rpy="${M_PI/2} 0 0" />
       <geometry>
         <sphere radius="${omni_wheel_radius}"/>
       </geometry>
     </collision-->
    <inertial>
      <mass value="1.0"/>
      <origin xyz="0 0 0"/>
      <inertia ixx="0.00023507499999999998" ixy="0" ixz="0" iyy="0.00023507499999999998" iyz="0" izz="0.0003901499999999999"/>
      <!-- inertia  ixx="0.001" ixy="0.0"  ixz="0.0"  iyy="0.001"  iyz="0.0"  izz="0.001" / -->
    </inertial>
  </link>
  <!-- joint name="joint_${name}_wheel" type="continuous" -->
  <joint name="rb1_omni_front_leftwheel_joint" type="fixed">
    <parent link="rb1_base_link"/>
    <child link="rb1_omni_front_leftwheel_link"/>
    <origin rpy="0 0 0" xyz="0.132 0.1535 0.027"/>
    <axis rpy="0 0 0" xyz="0 1 0"/>
    <limit effort="100" velocity="100"/>
    <joint_properties damping="0.0" friction="0.0"/>
  </joint>
  <!-- transmission name="${name}_wheel_joint_trans">
      <type>transmission_interface/SimpleTransmission</type>
      <joint name="joint_${name}_wheel" />
      <actuator name="${name}_wheel_joint_motor">
        <hardwareInterface>EffortJointInterface</hardwareInterface>
        <mechanicalReduction>1</mechanicalReduction>
      </actuator>
    </transmission -->
  <gazebo reference="rb1_omni_front_leftwheel">
    <mu1 value="0"/>
    <mu2 value="0"/>
    <kp value="10000000.0"/>
    <kd value="1.0"/>
    <fdir1 value="1 0 0"/>
    <material>Gazebo/Black</material>
    <turnGravityOff>false</turnGravityOff>
  </gazebo>
  <!--gazebo reference="${name}_wheel">
		<kp>500000.0</kp>
		<kd>10.0</kd>
		<mu1>10</mu1>
		<mu2>10</mu2>
		<fdir1>1 0 0</fdir1>
		<maxVel>1.0</maxVel>
		<minDepth>0.003</minDepth>
		<material>Gazebo/Black</material>
		<turnGravityOff>false</turnGravityOff>
		<implicitSpringDamper>1</implicitSpringDamper>
    </gazebo-->
  <!--WHEEL TIRE -->
  <link name="rb1_omni_front_rightwheel_link">
    <visual>
      <origin rpy="0 0 0" xyz="0 0 0"/>
      <geometry>
        <mesh filename="package://rb1_base_description/meshes/wheels/rb1v2_omniwheel.dae"/>
      </geometry>
    </visual>
    <collision>
      <origin rpy="1.5707963267948966 0 0" xyz="0 0 0"/>
      <geometry>
        <cylinder length="0.03" radius="0.051"/>
      </geometry>
    </collision>
    <!--collision>
      <origin xyz="0 0 0" rpy="${M_PI/2} 0 0" />
       <geometry>
         <sphere radius="${omni_wheel_radius}"/>
       </geometry>
     </collision-->
    <inertial>
      <mass value="1.0"/>
      <origin xyz="0 0 0"/>
      <inertia ixx="0.00023507499999999998" ixy="0" ixz="0" iyy="0.00023507499999999998" iyz="0" izz="0.0003901499999999999"/>
      <!-- inertia  ixx="0.001" ixy="0.0"  ixz="0.0"  iyy="0.001"  iyz="0.0"  izz="0.001" / -->
    </inertial>
  </link>
  <!-- joint name="joint_${name}_wheel" type="continuous" -->
  <joint name="rb1_omni_front_rightwheel_joint" type="fixed">
    <parent link="rb1_base_link"/>
    <child link="rb1_omni_front_rightwheel_link"/>
    <origin rpy="0 0 0" xyz="0.132 -0.1535 0.027"/>
    <axis rpy="0 0 0" xyz="0 1 0"/>
    <limit effort="100" velocity="100"/>
    <joint_properties damping="0.0" friction="0.0"/>
  </joint>
  <!-- transmission name="${name}_wheel_joint_trans">
      <type>transmission_interface/SimpleTransmission</type>
      <joint name="joint_${name}_wheel" />
      <actuator name="${name}_wheel_joint_motor">
        <hardwareInterface>EffortJointInterface</hardwareInterface>
        <mechanicalReduction>1</mechanicalReduction>
      </actuator>
    </transmission -->
  <gazebo reference="rb1_omni_front_rightwheel">
    <mu1 value="0"/>
    <mu2 value="0"/>
    <kp value="10000000.0"/>
    <kd value="1.0"/>
    <fdir1 value="1 0 0"/>
    <material>Gazebo/Black</material>
    <turnGravityOff>false</turnGravityOff>
  </gazebo>
  <!--gazebo reference="${name}_wheel">
		<kp>500000.0</kp>
		<kd>10.0</kd>
		<mu1>10</mu1>
		<mu2>10</mu2>
		<fdir1>1 0 0</fdir1>
		<maxVel>1.0</maxVel>
		<minDepth>0.003</minDepth>
		<material>Gazebo/Black</material>
		<turnGravityOff>false</turnGravityOff>
		<implicitSpringDamper>1</implicitSpringDamper>
    </gazebo-->
  <!-- SENSORS -->
  <link name="rb1_front_laser_link">
  <inertial>
      <mass value="0.0"/>
      <origin rpy="0 0 0" xyz="0 0 0"/>
      <inertia ixx="0.0" ixy="0.0" ixz="0.0" iyy="0.0" iyz="0.0" izz="0.0"/>
    </inertial>
	</link>
  <joint name="rb1_front_laser_joint" type="fixed">
    <parent link="rb1_base_link"/>
    <child link="rb1_front_laser_link"/>
    <origin rpy="0 3.1416 3.1416" xyz="0.210 0.0 0.159"/>
  </joint>
  <joint name="rb1_front_laser_base_joint" type="fixed">
    <origin rpy="0 0 0" xyz="0.00 0 -0.05"/>
    <parent link="rb1_front_laser_link"/>
    <child link="rb1_front_laser_base_link"/>
  </joint>
  <link name="rb1_front_laser_base_link">
    <collision>
      <origin rpy="0 0 0" xyz="0 0 0.0"/>
      <geometry>
        <box size="0.010 0.010 0.010"/>
      </geometry>
    </collision>
    <visual>
      <origin rpy="0 0 0" xyz="0 0 0.0"/>
      <geometry>
        <mesh filename="package://robotnik_sensors/meshes/hokuyo_ust_10lx.dae"/>
      </geometry>
    </visual>
    <inertial>
      <mass value="1e-5"/>
      <origin rpy="0 0 0" xyz="0 0 0"/>
      <inertia ixx="1e-6" ixy="0" ixz="0" iyy="1e-6" iyz="0" izz="1e-6"/>
    </inertial>
  </link>
  <gazebo reference="rb1_front_laser_link">
    <sensor name="rb1_front_laser_sensor" type="gpu_ray">
      <pose>0 0 0 0 0 0</pose>
      <visualize>false</visualize>
      <update_rate>40</update_rate>
      <ray>
        <scan>
          <horizontal>
            <samples>1081</samples>
            <resolution>1</resolution>
            <min_angle>-2.3562</min_angle>
            <max_angle>2.3562</max_angle>
          </horizontal>
        </scan>
        <range>
          <min>0.06</min>
          <max>10.0</max>
          <!-- resolution>0.004363323</resolution -->
          <resolution>0.004359297</resolution>
          <!-- resolution>0.001</resolution -->
        </range>
        <noise>
          <type>gaussian</type>
          <mean>0.0</mean>
          <stddev>0.01</stddev>
        </noise>
      </ray>
      <plugin filename="libgazebo_ros_gpu_laser.so" name="rb1_front_laser_controller">
        <topicName>front_laser/scan</topicName>
        <frameName>/rb1_front_laser_link</frameName>
      </plugin>
    </sensor>
  </gazebo>
  <joint name="rb1_imu_joint" type="fixed">
    <axis xyz="1 0 0"/>
    <!--origin xyz="0 0 0.2825"/-->
    <origin rpy="0 0 0" xyz="0.002 0.053 0.1485"/>
    <parent link="rb1_base_link"/>
    <child link="rb1_imu_link"/>
  </joint>
  <link name="rb1_imu_link">
    <inertial>
      <mass value="0.001"/>
      <origin rpy="0 0 0" xyz="0 0 0"/>
      <inertia ixx="0.0001" ixy="0" ixz="0" iyy="0.000001" iyz="0" izz="0.0001"/>
    </inertial>
    <visual>
      <origin rpy="0 0 0" xyz="0 0 0"/>
      <geometry>
        <box size="0.001 0.001 0.001"/>
      </geometry>
    </visual>
    <collision>
      <origin rpy="0 0 0" xyz="0 0 0"/>
      <geometry>
        <box size=".001 .001 .001"/>
      </geometry>
    </collision>
  </link>
  <gazebo>
    <plugin filename="libhector_gazebo_ros_imu.so" name="rb1_imu_controller">
      <alwaysOn>true</alwaysOn>
      <topicName>imu/data</topicName>
      <serviceName>rb1_imuimu/service</serviceName>
      <bodyName>rb1_imu_link</bodyName>
      <frameId>rb1_imu_link</frameId>
      <updateRate>50.0</updateRate>
      <gaussianNoise>0.00</gaussianNoise>
      <yawOffset>0.0</yawOffset>
      <yawDrift>0.0</yawDrift>
      <yawGaussianNoise>0.0</yawGaussianNoise>
      <!-- angular velocities parameters -->
      <rateOffset>0.0 0.0 0.0</rateOffset>
      <rateDrift>0.0 0.0 0.0</rateDrift>
      <rateGaussianNoise>0.0 0.0 0.0</rateGaussianNoise>
      <!-- linear accelerations parameters -->
      <accelOffset>0.0 0.0 0.0</accelOffset>
      <accelDrift>0.0 0.0 0.0</accelDrift>
      <accelGaussianNoise>0.0 0.0 0.0</accelGaussianNoise>
    </plugin>
  </gazebo>
  <joint name="rb1_front_rgbd_camera_rgb_joint" type="fixed">
    <origin rpy="0 0 0" xyz="0.234 0.0125 0.107"/>
    <parent link="rb1_base_link"/>
    <child link="rb1_front_rgbd_camera_rgb_base_link"/>
  </joint>
  <link name="rb1_front_rgbd_camera_rgb_base_link">
    <inertial>
      <mass value="0.001"/>
      <origin xyz="0 0 0"/>
      <inertia ixx="0.0001" ixy="0.0" ixz="0.0" iyy="0.0001" iyz="0.0" izz="0.0001"/>
    </inertial>
  </link>
  <joint name="rb1_front_rgbd_camera_rgb_optical_joint" type="fixed">
    <origin rpy="-1.5707963267948966 0 -1.5707963267948966" xyz="0.0 0.0 0.0"/>
    <parent link="rb1_front_rgbd_camera_rgb_base_link"/>
    <child link="rb1_front_rgbd_camera_rgb_optical_frame"/>
  </joint>
  <link name="rb1_front_rgbd_camera_rgb_optical_frame">
    <inertial>
        <mass value="0.001" />
        <origin xyz="0 0 0" />
        <inertia ixx="0.0001" ixy="0.0" ixz="0.0"
          iyy="0.0001" iyz="0.0"
          izz="0.0001" />
      </inertial>
  </link>
  <joint name="rb1_front_rgbd_camera_joint" type="fixed">
    <origin rpy="0.0 0 0" xyz="0.0 -0.0125 -0.015"/>
    <parent link="rb1_front_rgbd_camera_rgb_base_link"/>
    <child link="rb1_front_rgbd_camera_link"/>
  </joint>
  <link name="rb1_front_rgbd_camera_link">
    <visual>
      <origin rpy="0 0 0" xyz="0 0 0"/>
      <geometry>
        <mesh filename="package://robotnik_sensors/meshes/orbbec_astra.dae" scale="1.0 1.0 1.0"/>
      </geometry>
    </visual>
    <collision>
      <origin rpy="0 0 0" xyz="0.0 0.0 0.0"/>
      <!--geometry>
        <box size="0.0730 .2760 0.0720"/>
      </geometry-->
      <geometry>
        <mesh filename="package://robotnik_sensors/meshes/orbbec_astra.dae" scale="1.0 1.0 1.0"/>
      </geometry>
    </collision>
    <inertial>
      <!--mass value="0.01" />
        <origin xyz="0 0 0" />
        <inertia ixx="0.001" ixy="0.0" ixz="0.0"
          iyy="0.001" iyz="0.0"
          izz="0.001" /-->
      <mass value="0.564"/>
      <origin xyz="0 0 0"/>
      <inertia ixx="0.003881243" ixy="0.0" ixz="0.0" iyy="0.000498940" iyz="0.0" izz="0.003879257"/>
    </inertial>
  </link>
  <joint name="rb1_front_rgbd_camera_depth_joint" type="fixed">
    <origin rpy="0 0 0" xyz="0.0 0.025 0.0"/>
    <parent link="rb1_front_rgbd_camera_rgb_base_link"/>
    <child link="rb1_front_rgbd_camera_depth_frame"/>
  </joint>
  <link name="rb1_front_rgbd_camera_depth_frame">
    <inertial>
        <mass value="0.01" />
        <origin xyz="0 0 0" />
        <inertia ixx="0.001" ixy="0.0" ixz="0.0"
          iyy="0.001" iyz="0.0"
          izz="0.001" />
      </inertial>
  </link>
  <joint name="rb1_front_rgbd_camera_depth_optical_joint" type="fixed">
    <origin rpy="-1.5707963267948966 0 -1.5707963267948966" xyz="0 0 0"/>
    <parent link="rb1_front_rgbd_camera_depth_frame"/>
    <child link="rb1_front_rgbd_camera_depth_optical_frame"/>
  </joint>
  <link name="rb1_front_rgbd_camera_depth_optical_frame">
    <inertial>
        <mass value="0.001" />
        <origin xyz="0 0 0" />
        <inertia ixx="0.0001" ixy="0.0" ixz="0.0"
          iyy="0.0001" iyz="0.0"
          izz="0.0001" />
      </inertial>
  </link>
  <!-- RGBD sensor for simulation, same as Kinect -->
  <sensor_orbbec_astra_gazebo/>
  <!-- TORSO & ARMS -->
  <link name="rb1_torso_link">
    <visual>
      <origin rpy="0 0 0" xyz="0 0 0"/>
      <geometry>
        <mesh filename="package://rb1_base_description/meshes/others/rb1_torso_ur3.stl"/>
      </geometry>
    </visual>
    <collision>
      <origin rpy="0 0 0" xyz="0 0 0"/>
      <geometry>
        <mesh filename="package://rb1_base_description/meshes/others/rb1_torso_ur3.stl"/>
      </geometry>
    </collision>
    <inertial>
      <mass value="4.0"/>
      <origin xyz="0 0 0"/>
      <inertia ixx="0.154375" ixy="0" ixz="0" iyy="0.154375" iyz="0" izz="0.005000000000000001"/>
    </inertial>
  </link>
  <joint name="rb1_torso_joint" type="fixed">
    <parent link="rb1_base_footprint"/>
    <child link="rb1_torso_link"/>
    <origin rpy="0.0 0.0 0.0" xyz="-0.1 0.0 0.248"/>
    <axis rpy="0 0 0" xyz="0 0 1"/>
  </joint>
  <link name="rb1_torso_ur3_right_link">
  <inertial>
      <mass value="0.01"/>
      <origin xyz="0 0 0"/>
      <inertia ixx="0.1" ixy="0.0" ixz="0.0" iyy="0.1" iyz="0.0" izz="0.1"/>
    </inertial>
    </link>
  <joint name="rb1_torso_ur3_right_joint" type="fixed">
    <parent link="rb1_torso_link"/>
    <child link="rb1_torso_ur3_right_link"/>
    <origin rpy="0 -2.356194490192345 1.5707963267948966" xyz="0.17 -0.1655 0.954"/>
  </joint>
  <link name="rb1_torso_ur3_left_link">
  <inertial>
      <mass value="0.01"/>
      <origin xyz="0 0 0"/>
      <inertia ixx="0.1" ixy="0.0" ixz="0.0" iyy="0.1" iyz="0.0" izz="0.1"/>
    </inertial>
    </link>
  <joint name="rb1_torso_ur3_left_joint" type="fixed">
    <parent link="rb1_torso_link"/>
    <child link="rb1_torso_ur3_left_link"/>
    <origin rpy="0 -2.356194490192345 -1.5707963267948966" xyz="0.17 0.1655 0.954"/>
  </joint>
  <!-- measured from model -->
  <link name="rb1_right_arm_base_link">
    <visual>
      <origin rpy="0 0 3.141592653589793" xyz="0 0 0"/>
      <geometry>
        <mesh filename="package://ur_description/meshes/ur3/visual/base.dae"/>
      </geometry>
      <material name="LightGrey">
        <color rgba="0.7 0.7 0.7 1.0"/>
      </material>
    </visual>
    <collision>
      <origin rpy="0 0 3.141592653589793" xyz="0 0 0"/>
      <geometry>
        <mesh filename="package://ur_description/meshes/ur3/collision/base.stl"/>
      </geometry>
    </collision>
    <inertial>
      <mass value="2.0"/>
      <origin rpy="0 0 0" xyz="0.0 0.0 0.0"/>
      <inertia ixx="0.0030531654454" ixy="0.0" ixz="0.0" iyy="0.0030531654454" iyz="0.0" izz="0.005625"/>
    </inertial>
  </link>
  <joint name="rb1_right_arm_shoulder_pan_joint" type="revolute">
    <parent link="rb1_right_arm_base_link"/>
    <child link="rb1_right_arm_shoulder_link"/>
    <origin rpy="0 0 3.141592653589793" xyz="0 0 0.1519"/>
    <axis xyz="0 0 1"/>
    <limit effort="330.0" lower="-6.283185307179586" upper="6.283185307179586" velocity="2.16"/>
    <dynamics damping="0.0" friction="0.0"/>
  </joint>
  <link name="rb1_right_arm_shoulder_link">
    <visual>
      <origin rpy="0 0 3.141592653589793" xyz="0 0 0"/>
      <geometry>
        <mesh filename="package://ur_description/meshes/ur3/visual/shoulder.dae"/>
      </geometry>
      <material name="LightGrey">
        <color rgba="0.7 0.7 0.7 1.0"/>
      </material>
    </visual>
    <collision>
      <origin rpy="0 0 3.141592653589793" xyz="0 0 0"/>
      <geometry>
        <mesh filename="package://ur_description/meshes/ur3/collision/shoulder.stl"/>
      </geometry>
    </collision>
    <inertial>
      <mass value="2.0"/>
      <origin rpy="0 0 0" xyz="0.0 0.0 0.0"/>
      <inertia ixx="0.008093163429399999" ixy="0.0" ixz="0.0" iyy="0.008093163429399999" iyz="0.0" izz="0.005625"/>
    </inertial>
  </link>
  <joint name="rb1_right_arm_shoulder_lift_joint" type="revolute">
    <parent link="rb1_right_arm_shoulder_link"/>
    <child link="rb1_right_arm_upper_arm_link"/>
    <origin rpy="1.570796327 0 0" xyz="0 0 0"/>
    <axis xyz="0 0 1"/>
    <limit effort="330.0" lower="-6.283185307179586" upper="6.283185307179586" velocity="2.16"/>
    <dynamics damping="0.0" friction="0.0"/>
  </joint>
  <link name="rb1_right_arm_upper_arm_link">
    <visual>
      <origin rpy="1.5707963267948966 0 -1.5707963267948966" xyz="0 0 0.1198"/>
      <geometry>
        <mesh filename="package://ur_description/meshes/ur3/visual/upperarm.dae"/>
      </geometry>
      <material name="LightGrey">
        <color rgba="0.7 0.7 0.7 1.0"/>
      </material>
    </visual>
    <collision>
      <origin rpy="1.5707963267948966 0 -1.5707963267948966" xyz="0 0 0.1198"/>
      <geometry>
        <mesh filename="package://ur_description/meshes/ur3/collision/upperarm.stl"/>
      </geometry>
    </collision>
    <inertial>
      <mass value="3.42"/>
      <origin rpy="0 1.5707963267948966 0" xyz="-0.121825 0.0 0.12"/>
      <inertia ixx="0.021728483221103233" ixy="0.0" ixz="0.0" iyy="0.021728483221103233" iyz="0.0" izz="0.00961875"/>
    </inertial>
  </link>
  <joint name="rb1_right_arm_elbow_joint" type="revolute">
    <parent link="rb1_right_arm_upper_arm_link"/>
    <child link="rb1_right_arm_forearm_link"/>
    <origin rpy="0 0 0" xyz="-0.24365 0 0"/>
    <axis xyz="0 0 1"/>
    <limit effort="150.0" lower="-6.283185307179586" upper="6.283185307179586" velocity="3.15"/>
    <dynamics damping="0.0" friction="0.0"/>
  </joint>
  <link name="rb1_right_arm_forearm_link">
    <visual>
      <origin rpy="1.5707963267948966 0 -1.5707963267948966" xyz="0 0 0.0275"/>
      <geometry>
        <mesh filename="package://ur_description/meshes/ur3/visual/forearm.dae"/>
      </geometry>
      <material name="LightGrey">
        <color rgba="0.7 0.7 0.7 1.0"/>
      </material>
    </visual>
    <collision>
      <origin rpy="1.5707963267948966 0 -1.5707963267948966" xyz="0 0 0.0275"/>
      <geometry>
        <mesh filename="package://ur_description/meshes/ur3/collision/forearm.stl"/>
      </geometry>
    </collision>
    <inertial>
      <mass value="1.26"/>
      <origin rpy="0 1.5707963267948966 0" xyz="-0.121825 0.0 0.0275"/>
      <inertia ixx="0.006546806443776375" ixy="0.0" ixz="0.0" iyy="0.006546806443776375" iyz="0.0" izz="0.00354375"/>
    </inertial>
  </link>
  <joint name="rb1_right_arm_wrist_1_joint" type="revolute">
    <parent link="rb1_right_arm_forearm_link"/>
    <child link="rb1_right_arm_wrist_1_link"/>
    <origin rpy="0 0 0" xyz="-0.21325 0 0.11235"/>
    <axis xyz="0 0 1"/>
    <limit effort="54.0" lower="-6.283185307179586" upper="6.283185307179586" velocity="3.2"/>
    <dynamics damping="0.0" friction="0.0"/>
  </joint>
  <link name="rb1_right_arm_wrist_1_link">
    <visual>
      <origin rpy="1.5707963267948966 0 0" xyz="0 0 -0.085"/>
      <geometry>
        <mesh filename="package://ur_description/meshes/ur3/visual/wrist1.dae"/>
      </geometry>
      <material name="LightGrey">
        <color rgba="0.7 0.7 0.7 1.0"/>
      </material>
    </visual>
    <collision>
      <origin rpy="1.5707963267948966 0 0" xyz="0 0 -0.085"/>
      <geometry>
        <mesh filename="package://ur_description/meshes/ur3/collision/wrist1.stl"/>
      </geometry>
    </collision>
    <inertial>
      <mass value="0.8"/>
      <origin rpy="0 0 0" xyz="0.0 0.0 0.0"/>
      <inertia ixx="0.0016106408557434" ixy="0.0" ixz="0.0" iyy="0.0016106408557434" iyz="0.0" izz="0.00225"/>
    </inertial>
  </link>
  <joint name="rb1_right_arm_wrist_2_joint" type="revolute">
    <parent link="rb1_right_arm_wrist_1_link"/>
    <child link="rb1_right_arm_wrist_2_link"/>
    <origin rpy="1.570796327 0 0" xyz="0 -0.08535 -1.750557762378351e-11"/>
    <axis xyz="0 0 1"/>
    <limit effort="54.0" lower="-6.283185307179586" upper="6.283185307179586" velocity="3.2"/>
    <dynamics damping="0.0" friction="0.0"/>
  </joint>
  <link name="rb1_right_arm_wrist_2_link">
    <visual>
      <origin rpy="0 0 0" xyz="0 0 -0.085"/>
      <geometry>
        <mesh filename="package://ur_description/meshes/ur3/visual/wrist2.dae"/>
      </geometry>
      <material name="LightGrey">
        <color rgba="0.7 0.7 0.7 1.0"/>
      </material>
    </visual>
    <collision>
      <origin rpy="0 0 0" xyz="0 0 -0.085"/>
      <geometry>
        <mesh filename="package://ur_description/meshes/ur3/collision/wrist2.stl"/>
      </geometry>
    </collision>
    <inertial>
      <mass value="0.8"/>
      <origin rpy="0 0 0" xyz="0.0 0.0 0.0"/>
      <inertia ixx="0.0015721733711303997" ixy="0.0" ixz="0.0" iyy="0.0015721733711303997" iyz="0.0" izz="0.00225"/>
    </inertial>
  </link>
  <joint name="rb1_right_arm_wrist_3_joint" type="revolute">
    <parent link="rb1_right_arm_wrist_2_link"/>
    <child link="rb1_right_arm_wrist_3_link"/>
    <origin rpy="1.570796326589793 3.141592653589793 3.141592653589793" xyz="0 0.0819 -1.679797079540562e-11"/>
    <axis xyz="0 0 1"/>
    <limit effort="54.0" lower="-6.283185307179586" upper="6.283185307179586" velocity="3.2"/>
    <dynamics damping="0.0" friction="0.0"/>
  </joint>
  <link name="rb1_right_arm_wrist_3_link">
    <visual>
      <origin rpy="1.5707963267948966 0 0" xyz="0 0 -0.082"/>
      <geometry>
        <mesh filename="package://ur_description/meshes/ur3/visual/wrist3.dae"/>
      </geometry>
      <material name="LightGrey">
        <color rgba="0.7 0.7 0.7 1.0"/>
      </material>
    </visual>
    <collision>
      <origin rpy="1.5707963267948966 0 0" xyz="0 0 -0.082"/>
      <geometry>
        <mesh filename="package://ur_description/meshes/ur3/collision/wrist3.stl"/>
      </geometry>
    </collision>
    <inertial>
      <mass value="0.35"/>
      <origin rpy="0 0 0" xyz="0.0 0.0 -0.01525"/>
      <inertia ixx="0.00020431970993874997" ixy="0.0" ixz="0.0" iyy="0.00020431970993874997" iyz="0.0" izz="0.000354375"/>
    </inertial>
  </link>
  <joint name="rb1_right_arm_ee_fixed_joint" type="fixed">
    <parent link="rb1_right_arm_wrist_3_link"/>
    <child link="rb1_right_arm_ee_link"/>
    <origin rpy="0.0 -1.5707963267948966 1.5707963267948966" xyz="0.0 0.0 0.0"/>
  </joint>
  <link name="rb1_right_arm_ee_link">
    <collision>
      <geometry>
        <box size="0.01 0.01 0.01"/>
      </geometry>
      <origin rpy="0 0 0" xyz="-0.01 0 0"/>
    </collision>
    <inertial>
      <mass value="0.1"/>
      <origin rpy="0 0 0" xyz="0.0 0.0 0.0"/>
      <inertia ixx="0.1" ixy="0.0" ixz="0.0" iyy="0.1" iyz="0.0" izz="0.1"/>
    </inertial>
  </link>
  <joint name="rb1_right_arm_wrist_3_passive_joint" type="fixed">
    <origin rpy="0 0 0" xyz="0 0 0"/>
    <parent link="rb1_right_arm_wrist_3_link"/>
    <child link="rb1_right_arm_tool0"/>
  </joint>
  <transmission name="rb1_right_arm_shoulder_pan_trans">
    <type>transmission_interface/SimpleTransmission</type>
    <joint name="rb1_right_arm_shoulder_pan_joint">
      <hardwareInterface>hardware_interface/PositionJointInterface</hardwareInterface>
    </joint>
    <actuator name="rb1_right_arm_shoulder_pan_motor">
      <mechanicalReduction>1</mechanicalReduction>
    </actuator>
  </transmission>
  <transmission name="rb1_right_arm_shoulder_lift_trans">
    <type>transmission_interface/SimpleTransmission</type>
    <joint name="rb1_right_arm_shoulder_lift_joint">
      <hardwareInterface>hardware_interface/PositionJointInterface</hardwareInterface>
    </joint>
    <actuator name="rb1_right_arm_shoulder_lift_motor">
      <mechanicalReduction>1</mechanicalReduction>
    </actuator>
  </transmission>
  <transmission name="rb1_right_arm_elbow_trans">
    <type>transmission_interface/SimpleTransmission</type>
    <joint name="rb1_right_arm_elbow_joint">
      <hardwareInterface>hardware_interface/PositionJointInterface</hardwareInterface>
    </joint>
    <actuator name="rb1_right_arm_elbow_motor">
      <mechanicalReduction>1</mechanicalReduction>
    </actuator>
  </transmission>
  <transmission name="rb1_right_arm_wrist_1_trans">
    <type>transmission_interface/SimpleTransmission</type>
    <joint name="rb1_right_arm_wrist_1_joint">
      <hardwareInterface>hardware_interface/PositionJointInterface</hardwareInterface>
    </joint>
    <actuator name="rb1_right_arm_wrist_1_motor">
      <mechanicalReduction>1</mechanicalReduction>
    </actuator>
  </transmission>
  <transmission name="rb1_right_arm_wrist_2_trans">
    <type>transmission_interface/SimpleTransmission</type>
    <joint name="rb1_right_arm_wrist_2_joint">
      <hardwareInterface>hardware_interface/PositionJointInterface</hardwareInterface>
    </joint>
    <actuator name="rb1_right_arm_wrist_2_motor">
      <mechanicalReduction>1</mechanicalReduction>
    </actuator>
  </transmission>
  <transmission name="rb1_right_arm_wrist_3_trans">
    <type>transmission_interface/SimpleTransmission</type>
    <joint name="rb1_right_arm_wrist_3_joint">
      <hardwareInterface>hardware_interface/PositionJointInterface</hardwareInterface>
    </joint>
    <actuator name="rb1_right_arm_wrist_3_motor">
      <mechanicalReduction>1</mechanicalReduction>
    </actuator>
  </transmission>
  <gazebo reference="rb1_right_arm_shoulder_link">
    <selfCollide>true</selfCollide>
  </gazebo>
  <gazebo reference="rb1_right_arm_upper_arm_link">
    <selfCollide>true</selfCollide>
  </gazebo>
  <gazebo reference="rb1_right_arm_forearm_link">
    <selfCollide>true</selfCollide>
  </gazebo>
  <gazebo reference="rb1_right_arm_wrist_1_link">
    <selfCollide>true</selfCollide>
  </gazebo>
  <gazebo reference="rb1_right_arm_wrist_3_link">
    <selfCollide>true</selfCollide>
  </gazebo>
  <gazebo reference="rb1_right_arm_wrist_2_link">
    <selfCollide>true</selfCollide>
  </gazebo>
  <gazebo reference="rb1_right_arm_ee_link">
    <selfCollide>true</selfCollide>
  </gazebo>
  <!-- ROS base_link to UR 'Base' Coordinates transform -->
  <link name="rb1_right_arm_base">
  <inertial>
      <mass value="0.0"/>
      <origin rpy="0 0 0" xyz="0.0 0.0 0.0"/>
      <inertia ixx="0.0" ixy="0.0" ixz="0.0" iyy="0.0" iyz="0.0" izz="0.0"/>
    </inertial>
  </link>
  <joint name="rb1_right_arm_base_link-base_fixed_joint" type="fixed">
    <!-- NOTE: this rotation is only needed as long as base_link itself is
                 not corrected wrt the real robot (ie: rotated over 180
                 degrees)
      -->
    <origin rpy="0 0 -3.141592653589793" xyz="0 0 0"/>
    <parent link="rb1_right_arm_base_link"/>
    <child link="rb1_right_arm_base"/>
  </joint>
  <!-- Frame coincident with all-zeros TCP on UR controller -->
  <link name="rb1_right_arm_tool0">
  <inertial>
      <mass value="0.1"/>
      <origin rpy="0 0 0" xyz="0.0 0.0 0.0"/>
      <inertia ixx="0.1" ixy="0.0" ixz="0.0" iyy="0.1" iyz="0.0" izz="0.1"/>
  </inertial>
  </link>
  <joint name="rb1_right_arm_base_joint" type="fixed">
    <origin rpy="0.0 0.0 0.0" xyz="0.0 0.0 0.0"/>
    <parent link="rb1_torso_ur3_right_link"/>
    <child link="rb1_right_arm_base_link"/>
  </joint>
  <!-- measured from model -->
  <link name="rb1_left_arm_base_link">
    <visual>
      <origin rpy="0 0 3.141592653589793" xyz="0 0 0"/>
      <geometry>
        <mesh filename="package://ur_description/meshes/ur3/visual/base.dae"/>
      </geometry>
      <material name="LightGrey">
        <color rgba="0.7 0.7 0.7 1.0"/>
      </material>
    </visual>
    <collision>
      <origin rpy="0 0 3.141592653589793" xyz="0 0 0"/>
      <geometry>
        <mesh filename="package://ur_description/meshes/ur3/collision/base.stl"/>
      </geometry>
    </collision>
    <inertial>
      <mass value="2.0"/>
      <origin rpy="0 0 0" xyz="0.0 0.0 0.0"/>
      <inertia ixx="0.0030531654454" ixy="0.0" ixz="0.0" iyy="0.0030531654454" iyz="0.0" izz="0.005625"/>
    </inertial>
  </link>
  <joint name="rb1_left_arm_shoulder_pan_joint" type="revolute">
    <parent link="rb1_left_arm_base_link"/>
    <child link="rb1_left_arm_shoulder_link"/>
    <origin rpy="0 0 3.141592653589793" xyz="0 0 0.1519"/>
    <axis xyz="0 0 1"/>
    <limit effort="330.0" lower="-6.283185307179586" upper="6.283185307179586" velocity="2.16"/>
    <dynamics damping="0.0" friction="0.0"/>
  </joint>
  <link name="rb1_left_arm_shoulder_link">
    <visual>
      <origin rpy="0 0 3.141592653589793" xyz="0 0 0"/>
      <geometry>
        <mesh filename="package://ur_description/meshes/ur3/visual/shoulder.dae"/>
      </geometry>
      <material name="LightGrey">
        <color rgba="0.7 0.7 0.7 1.0"/>
      </material>
    </visual>
    <collision>
      <origin rpy="0 0 3.141592653589793" xyz="0 0 0"/>
      <geometry>
        <mesh filename="package://ur_description/meshes/ur3/collision/shoulder.stl"/>
      </geometry>
    </collision>
    <inertial>
      <mass value="2.0"/>
      <origin rpy="0 0 0" xyz="0.0 0.0 0.0"/>
      <inertia ixx="0.008093163429399999" ixy="0.0" ixz="0.0" iyy="0.008093163429399999" iyz="0.0" izz="0.005625"/>
    </inertial>
  </link>
  <joint name="rb1_left_arm_shoulder_lift_joint" type="revolute">
    <parent link="rb1_left_arm_shoulder_link"/>
    <child link="rb1_left_arm_upper_arm_link"/>
    <origin rpy="1.570796327 0 0" xyz="0 0 0"/>
    <axis xyz="0 0 1"/>
    <limit effort="330.0" lower="-6.283185307179586" upper="6.283185307179586" velocity="2.16"/>
    <dynamics damping="0.0" friction="0.0"/>
  </joint>
  <link name="rb1_left_arm_upper_arm_link">
    <visual>
      <origin rpy="1.5707963267948966 0 -1.5707963267948966" xyz="0 0 0.1198"/>
      <geometry>
        <mesh filename="package://ur_description/meshes/ur3/visual/upperarm.dae"/>
      </geometry>
      <material name="LightGrey">
        <color rgba="0.7 0.7 0.7 1.0"/>
      </material>
    </visual>
    <collision>
      <origin rpy="1.5707963267948966 0 -1.5707963267948966" xyz="0 0 0.1198"/>
      <geometry>
        <mesh filename="package://ur_description/meshes/ur3/collision/upperarm.stl"/>
      </geometry>
    </collision>
    <inertial>
      <mass value="3.42"/>
      <origin rpy="0 1.5707963267948966 0" xyz="-0.121825 0.0 0.12"/>
      <inertia ixx="0.021728483221103233" ixy="0.0" ixz="0.0" iyy="0.021728483221103233" iyz="0.0" izz="0.00961875"/>
    </inertial>
  </link>
  <joint name="rb1_left_arm_elbow_joint" type="revolute">
    <parent link="rb1_left_arm_upper_arm_link"/>
    <child link="rb1_left_arm_forearm_link"/>
    <origin rpy="0 0 0" xyz="-0.24365 0 0"/>
    <axis xyz="0 0 1"/>
    <limit effort="150.0" lower="-6.283185307179586" upper="6.283185307179586" velocity="3.15"/>
    <dynamics damping="0.0" friction="0.0"/>
  </joint>
  <link name="rb1_left_arm_forearm_link">
    <visual>
      <origin rpy="1.5707963267948966 0 -1.5707963267948966" xyz="0 0 0.0275"/>
      <geometry>
        <mesh filename="package://ur_description/meshes/ur3/visual/forearm.dae"/>
      </geometry>
      <material name="LightGrey">
        <color rgba="0.7 0.7 0.7 1.0"/>
      </material>
    </visual>
    <collision>
      <origin rpy="1.5707963267948966 0 -1.5707963267948966" xyz="0 0 0.0275"/>
      <geometry>
        <mesh filename="package://ur_description/meshes/ur3/collision/forearm.stl"/>
      </geometry>
    </collision>
    <inertial>
      <mass value="1.26"/>
      <origin rpy="0 1.5707963267948966 0" xyz="-0.121825 0.0 0.0275"/>
      <inertia ixx="0.006546806443776375" ixy="0.0" ixz="0.0" iyy="0.006546806443776375" iyz="0.0" izz="0.00354375"/>
    </inertial>
  </link>
  <joint name="rb1_left_arm_wrist_1_joint" type="revolute">
    <parent link="rb1_left_arm_forearm_link"/>
    <child link="rb1_left_arm_wrist_1_link"/>
    <origin rpy="0 0 0" xyz="-0.21325 0 0.11235"/>
    <axis xyz="0 0 1"/>
    <limit effort="54.0" lower="-6.283185307179586" upper="6.283185307179586" velocity="3.2"/>
    <dynamics damping="0.0" friction="0.0"/>
  </joint>
  <link name="rb1_left_arm_wrist_1_link">
    <visual>
      <origin rpy="1.5707963267948966 0 0" xyz="0 0 -0.085"/>
      <geometry>
        <mesh filename="package://ur_description/meshes/ur3/visual/wrist1.dae"/>
      </geometry>
      <material name="LightGrey">
        <color rgba="0.7 0.7 0.7 1.0"/>
      </material>
    </visual>
    <collision>
      <origin rpy="1.5707963267948966 0 0" xyz="0 0 -0.085"/>
      <geometry>
        <mesh filename="package://ur_description/meshes/ur3/collision/wrist1.stl"/>
      </geometry>
    </collision>
    <inertial>
      <mass value="0.8"/>
      <origin rpy="0 0 0" xyz="0.0 0.0 0.0"/>
      <inertia ixx="0.0016106408557434" ixy="0.0" ixz="0.0" iyy="0.0016106408557434" iyz="0.0" izz="0.00225"/>
    </inertial>
  </link>
  <joint name="rb1_left_arm_wrist_2_joint" type="revolute">
    <parent link="rb1_left_arm_wrist_1_link"/>
    <child link="rb1_left_arm_wrist_2_link"/>
    <origin rpy="1.570796327 0 0" xyz="0 -0.08535 -1.750557762378351e-11"/>
    <axis xyz="0 0 1"/>
    <limit effort="54.0" lower="-6.283185307179586" upper="6.283185307179586" velocity="3.2"/>
    <dynamics damping="0.0" friction="0.0"/>
  </joint>
  <link name="rb1_left_arm_wrist_2_link">
    <visual>
      <origin rpy="0 0 0" xyz="0 0 -0.085"/>
      <geometry>
        <mesh filename="package://ur_description/meshes/ur3/visual/wrist2.dae"/>
      </geometry>
      <material name="LightGrey">
        <color rgba="0.7 0.7 0.7 1.0"/>
      </material>
    </visual>
    <collision>
      <origin rpy="0 0 0" xyz="0 0 -0.085"/>
      <geometry>
        <mesh filename="package://ur_description/meshes/ur3/collision/wrist2.stl"/>
      </geometry>
    </collision>
    <inertial>
      <mass value="0.8"/>
      <origin rpy="0 0 0" xyz="0.0 0.0 0.0"/>
      <inertia ixx="0.0015721733711303997" ixy="0.0" ixz="0.0" iyy="0.0015721733711303997" iyz="0.0" izz="0.00225"/>
    </inertial>
  </link>
  <joint name="rb1_left_arm_wrist_3_joint" type="revolute">
    <parent link="rb1_left_arm_wrist_2_link"/>
    <child link="rb1_left_arm_wrist_3_link"/>
    <origin rpy="1.570796326589793 3.141592653589793 3.141592653589793" xyz="0 0.0819 -1.679797079540562e-11"/>
    <axis xyz="0 0 1"/>
    <limit effort="54.0" lower="-6.283185307179586" upper="6.283185307179586" velocity="3.2"/>
    <dynamics damping="0.0" friction="0.0"/>
  </joint>
  <link name="rb1_left_arm_wrist_3_link">
    <visual>
      <origin rpy="1.5707963267948966 0 0" xyz="0 0 -0.082"/>
      <geometry>
        <mesh filename="package://ur_description/meshes/ur3/visual/wrist3.dae"/>
      </geometry>
      <material name="LightGrey">
        <color rgba="0.7 0.7 0.7 1.0"/>
      </material>
    </visual>
    <collision>
      <origin rpy="1.5707963267948966 0 0" xyz="0 0 -0.082"/>
      <geometry>
        <mesh filename="package://ur_description/meshes/ur3/collision/wrist3.stl"/>
      </geometry>
    </collision>
    <inertial>
      <mass value="0.35"/>
      <origin rpy="0 0 0" xyz="0.0 0.0 -0.01525"/>
      <inertia ixx="0.00020431970993874997" ixy="0.0" ixz="0.0" iyy="0.00020431970993874997" iyz="0.0" izz="0.000354375"/>
    </inertial>
  </link>
  <joint name="rb1_left_arm_ee_fixed_joint" type="fixed">
    <parent link="rb1_left_arm_wrist_3_link"/>
    <child link="rb1_left_arm_ee_link"/>
    <origin rpy="0.0 -1.5707963267948966 1.5707963267948966" xyz="0.0 0.0 0.0"/>
  </joint>
  <link name="rb1_left_arm_ee_link">
    <collision>
      <geometry>
        <box size="0.01 0.01 0.01"/>
      </geometry>
      <origin rpy="0 0 0" xyz="-0.01 0 0"/>
    </collision>
    <inertial>
      <mass value="0.0"/>
      <origin rpy="0 0 0" xyz="0.0 0.0 0.0"/>
      <inertia ixx="0.00000" ixy="0.0" ixz="0.0" iyy="0.00000" iyz="0.0" izz="0.000000"/>
    </inertial>
  </link>
  <joint name="rb1_left_arm_wrist_3_passive_joint" type="fixed">
    <origin rpy="0 0 0" xyz="0 0 0"/>
    <parent link="rb1_left_arm_wrist_3_link"/>
    <child link="rb1_left_arm_tool0"/>
  </joint>
  <transmission name="rb1_left_arm_shoulder_pan_trans">
    <type>transmission_interface/SimpleTransmission</type>
    <joint name="rb1_left_arm_shoulder_pan_joint">
      <hardwareInterface>hardware_interface/PositionJointInterface</hardwareInterface>
    </joint>
    <actuator name="rb1_left_arm_shoulder_pan_motor">
      <mechanicalReduction>1</mechanicalReduction>
    </actuator>
  </transmission>
  <transmission name="rb1_left_arm_shoulder_lift_trans">
    <type>transmission_interface/SimpleTransmission</type>
    <joint name="rb1_left_arm_shoulder_lift_joint">
      <hardwareInterface>hardware_interface/PositionJointInterface</hardwareInterface>
    </joint>
    <actuator name="rb1_left_arm_shoulder_lift_motor">
      <mechanicalReduction>1</mechanicalReduction>
    </actuator>
  </transmission>
  <transmission name="rb1_left_arm_elbow_trans">
    <type>transmission_interface/SimpleTransmission</type>
    <joint name="rb1_left_arm_elbow_joint">
      <hardwareInterface>hardware_interface/PositionJointInterface</hardwareInterface>
    </joint>
    <actuator name="rb1_left_arm_elbow_motor">
      <mechanicalReduction>1</mechanicalReduction>
    </actuator>
  </transmission>
  <transmission name="rb1_left_arm_wrist_1_trans">
    <type>transmission_interface/SimpleTransmission</type>
    <joint name="rb1_left_arm_wrist_1_joint">
      <hardwareInterface>hardware_interface/PositionJointInterface</hardwareInterface>
    </joint>
    <actuator name="rb1_left_arm_wrist_1_motor">
      <mechanicalReduction>1</mechanicalReduction>
    </actuator>
  </transmission>
  <transmission name="rb1_left_arm_wrist_2_trans">
    <type>transmission_interface/SimpleTransmission</type>
    <joint name="rb1_left_arm_wrist_2_joint">
      <hardwareInterface>hardware_interface/PositionJointInterface</hardwareInterface>
    </joint>
    <actuator name="rb1_left_arm_wrist_2_motor">
      <mechanicalReduction>1</mechanicalReduction>
    </actuator>
  </transmission>
  <transmission name="rb1_left_arm_wrist_3_trans">
    <type>transmission_interface/SimpleTransmission</type>
    <joint name="rb1_left_arm_wrist_3_joint">
      <hardwareInterface>hardware_interface/PositionJointInterface</hardwareInterface>
    </joint>
    <actuator name="rb1_left_arm_wrist_3_motor">
      <mechanicalReduction>1</mechanicalReduction>
    </actuator>
  </transmission>
  <gazebo reference="rb1_left_arm_shoulder_link">
    <selfCollide>true</selfCollide>
  </gazebo>
  <gazebo reference="rb1_left_arm_upper_arm_link">
    <selfCollide>true</selfCollide>
  </gazebo>
  <gazebo reference="rb1_left_arm_forearm_link">
    <selfCollide>true</selfCollide>
  </gazebo>
  <gazebo reference="rb1_left_arm_wrist_1_link">
    <selfCollide>true</selfCollide>
  </gazebo>
  <gazebo reference="rb1_left_arm_wrist_3_link">
    <selfCollide>true</selfCollide>
  </gazebo>
  <gazebo reference="rb1_left_arm_wrist_2_link">
    <selfCollide>true</selfCollide>
  </gazebo>
  <gazebo reference="rb1_left_arm_ee_link">
    <selfCollide>true</selfCollide>
  </gazebo>
  <!-- ROS base_link to UR 'Base' Coordinates transform -->
  <link name="rb1_left_arm_base">
  <inertial>
      <mass value="0.0"/>
      <origin rpy="0 0 0" xyz="0.0 0.0 0.0"/>
      <inertia ixx="0.0" ixy="0.0" ixz="0.0" iyy="0.0" iyz="0.0" izz="0.0"/>
    </inertial>
  </link>
  <joint name="rb1_left_arm_base_link-base_fixed_joint" type="fixed">
    <!-- NOTE: this rotation is only needed as long as base_link itself is
                 not corrected wrt the real robot (ie: rotated over 180
                 degrees)
      -->
    <origin rpy="0 0 -3.141592653589793" xyz="0 0 0"/>
    <parent link="rb1_left_arm_base_link"/>
    <child link="rb1_left_arm_base"/>
  </joint>
  <!-- Frame coincident with all-zeros TCP on UR controller -->
  <link name="rb1_left_arm_tool0">
  <inertial>
      <mass value="0.00"/>
      <origin rpy="0 0 0" xyz="0.0 0.0 0.0"/>
      <inertia ixx="0.0" ixy="0.0" ixz="0.0" iyy="0.0" iyz="0.0" izz="0.0"/>
    </inertial>
  </link>
  <joint name="rb1_left_arm_base_joint" type="fixed">
    <origin rpy="0.0 0.0 0.0" xyz="0.0 0.0 0.0"/>
    <parent link="rb1_torso_ur3_left_link"/>
    <child link="rb1_left_arm_base_link"/>
  </joint>
  <!--link name="world"/-->
  
  <!-- Parte manos roboticas>
  <link name="R_hand_base_link">
    <inertial>
      <origin rpy="0 0 0" xyz="-0.076223 -0.01701 0.24616"/>
      <mass value="0.14143"/>
      <inertia ixx="7.6663E-05" ixy="1.6551E-06" ixz="1.7709E-06" iyy="8.3832E-05" iyz="-2.1711E-06" izz="0.00012281"/>
    </inertial>
    <visual>
      <origin rpy="0 0 0" xyz="0 0 0"/>
      <geometry>
        <mesh filename="package://inspire_hand_r/meshes/R_hand_base_link.STL"/>
      </geometry>
      <material name="">
        <color rgba="1 1 1 1"/>
      </material>
    </visual>
    <collision>
      <origin rpy="0 0 0" xyz="0 0 0"/>
      <geometry>
        <mesh filename="package://inspire_hand_r/meshes/R_hand_base_link.STL"/>
      </geometry>
    </collision>
  </link>
  <link name="R_thumb_proximal_base">
    <inertial>
      <origin rpy="0 0 0" xyz="-0.0048772 -0.010163 0.00044069"/>
      <mass value="0.0018869"/>
      <inertia ixx="5.2002E-08" ixy="4.8353E-09" ixz="-6.6441E-09" iyy="6.7433E-08" iyz="5.4472E-10" izz="8.5319E-08"/>
    </inertial>
    <visual>
      <origin rpy="0 0 0" xyz="0 0 0"/>
      <geometry>
        <mesh filename="package://inspire_hand_r/meshes/R_thumb_proximal_base.STL"/>
      </geometry>
      <material name="">
        <color rgba="1 1 1 1"/>
      </material>
    </visual>
    <collision>
      <origin rpy="0 0 0" xyz="0 0 0"/>
      <geometry>
        <mesh filename="package://inspire_hand_r/meshes/R_thumb_proximal_base.STL"/>
      </geometry>
    </collision>
  </link>
  <joint name="R_thumb_MCP_joint1" type="revolute">
    <origin rpy="1.5708 0 -0.28289" xyz="-0.098633 -0.23173 -0.011364"/>
    <parent link="R_hand_base_link"/>
    <child link="R_thumb_proximal_base"/>
    <axis xyz="0 -1 0"/>
    <limit effort="50" lower="0.2" upper="1.3" velocity="1"/>
  </joint>
  <link name="R_thumb_proximal">
    <inertial>
      <origin rpy="0 0 0" xyz="-3.8592E-05 0.02533 -0.0017007"/>
      <mass value="0.0066075"/>
      <inertia ixx="2.786E-06" ixy="1.673E-10" ixz="-1.3436E-09" iyy="8.9422E-07" iyz="-2.1394E-07" izz="2.4097E-06"/>
    </inertial>
    <visual>
      <origin rpy="0 0 0" xyz="0 0 0"/>
      <geometry>
        <mesh filename="package://inspire_hand_r/meshes/R_thumb_proximal.STL"/>
      </geometry>
      <material name="">
        <color rgba="1 1 1 1"/>
      </material>
    </visual>
    <collision>
      <origin rpy="0 0 0" xyz="0 0 0"/>
      <geometry>
        <mesh filename="package://inspire_hand_r/meshes/R_thumb_proximal.STL"/>
      </geometry>
    </collision>
  </link>
  <joint name="R_thumb_MCP_joint2" type="revolute">
    <origin rpy="0.97599 1.5708 0" xyz="-0.0115 -0.011843 0"/>
    <parent link="R_thumb_proximal_base"/>
    <child link="R_thumb_proximal"/>
    <axis xyz="-1 0 0"/>
    <limit effort="50" lower="1.3" upper="1.8" velocity="1"/>
  </joint>
  <link name="R_thumb_intermediate">
    <inertial>
      <origin rpy="0 0 0" xyz="2.8437E-07 0.0072526 -0.0064293"/>
      <mass value="0.0037847"/>
      <inertia ixx="4.6531E-07" ixy="-3.454E-12" ixz="3.4344E-12" iyy="2.6858E-07" iyz="-6.414E-08" izz="4.2517E-07"/>
    </inertial>
    <visual>
      <origin rpy="0 0 0" xyz="0 0 0"/>
      <geometry>
        <mesh filename="package://inspire_hand_r/meshes/R_thumb_intermediate.STL"/>
      </geometry>
      <material name="">
        <color rgba="1 1 1 1"/>
      </material>
    </visual>
    <collision>
      <origin rpy="0 0 0" xyz="0 0 0"/>
      <geometry>
        <mesh filename="package://inspire_hand_r/meshes/R_thumb_intermediate.STL"/>
      </geometry>
    </collision>
  </link>
  <joint name="R_thumb_PIP_joint" type="revolute">
    <origin rpy="-0.038299 0 0" xyz="0 0.055863 0.0039241"/>
    <parent link="R_thumb_proximal"/>
    <child link="R_thumb_intermediate"/>
    <axis xyz="1 0 0"/>
    <limit effort="50" lower="0" upper="1" velocity="1"/>
  </joint>
  <link name="R_thumb_distal">
    <inertial>
      <origin rpy="0 0 0" xyz="-3.3054E-06 0.010511 -0.00057863"/>
      <mass value="0.0033441"/>
      <inertia ixx="2.0026E-07" ixy="-1.4303E-10" ixz="-5.6945E-11" iyy="8.711E-08" iyz="-2.4416E-08" izz="1.8974E-07"/>
    </inertial>
    <visual>
      <origin rpy="0 0 0" xyz="0 0 0"/>
      <geometry>
        <mesh filename="package://inspire_hand_r/meshes/R_thumb_distal.STL"/>
      </geometry>
      <material name="">
        <color rgba="1 1 1 1"/>
      </material>
    </visual>
    <collision>
      <origin rpy="0 0 0" xyz="0 0 0"/>
      <geometry>
        <mesh filename="package://inspire_hand_r/meshes/R_thumb_distal.STL"/>
      </geometry>
    </collision>
  </link>
  <joint name="R_thumb_DIP_joint" type="revolute">
    <origin rpy="-0.011642 0 0" xyz="0 0.022558 -0.0020717"/>
    <parent link="R_thumb_intermediate"/>
    <child link="R_thumb_distal"/>
    <axis xyz="1 0 0"/>
    <limit effort="50" lower="0" upper="1.2" velocity="1"/>
  </joint>
  <link name="R_index_proximal">
    <inertial>
      <origin rpy="0 0 0" xyz="0.0099008 0.011884 0.0016958"/>
      <mass value="0.0042403"/>
      <inertia ixx="6.9398E-07" ixy="-4.4846E-12" ixz="-3.0248E-12" iyy="2.3039E-07" iyz="-9.1779E-08" izz="6.434E-07"/>
    </inertial>
    <visual>
      <origin rpy="0 0 0" xyz="0 0 0"/>
      <geometry>
        <mesh filename="package://inspire_hand_r/meshes/R_index_proximal.STL"/>
      </geometry>
      <material name="">
        <color rgba="1 1 1 1"/>
      </material>
    </visual>
    <collision>
      <origin rpy="0 0 0" xyz="0 0 0"/>
      <geometry>
        <mesh filename="package://inspire_hand_r/meshes/R_index_proximal.STL"/>
      </geometry>
    </collision>
  </link>
  <joint name="R_index_MCP_joint" type="revolute">
    <origin rpy="1.3268 0.034907 3.1416" xyz="-0.094559 -0.24897 0.054025"/>
    <parent link="R_hand_base_link"/>
    <child link="R_index_proximal"/>
    <axis xyz="1 0 0"/>
    <limit effort="50" lower="0" upper="1.7" velocity="1"/>
  </joint>
  <link name="R_index_distal">
    <inertial>
      <origin rpy="0 0 0" xyz="0.0083258 0.019591 0.0019565"/>
      <mass value="0.0045683"/>
      <inertia ixx="7.8179E-07" ixy="9.0022E-13" ixz="5.6729E-13" iyy="1.5635E-07" iyz="-2.1007E-07" izz="7.0084E-07"/>
    </inertial>
    <visual>
      <origin rpy="0 0 0" xyz="0 0 0"/>
      <geometry>
        <mesh filename="package://inspire_hand_r/meshes/R_index_distal.STL"/>
      </geometry>
      <material name="">
        <color rgba="1 1 1 1"/>
      </material>
    </visual>
    <collision>
      <origin rpy="0 0 0" xyz="0 0 0"/>
      <geometry>
        <mesh filename="package://inspire_hand_r/meshes/R_index_distal.STL"/>
      </geometry>
    </collision>
  </link>
  <joint name="R_index_DIP_joint" type="revolute">
    <origin rpy="0.044288 0 0" xyz="0.001575 0.030445 0.010275"/>
    <parent link="R_index_proximal"/>
    <child link="R_index_distal"/>
    <axis xyz="1 0 0"/>
    <limit effort="50" lower="0" upper="1.6" velocity="1"/>
  </joint>
  <link name="R_middle_proximal">
    <inertial>
      <origin rpy="0 0 0" xyz="0.008065 0.011884 0.0016958"/>
      <mass value="0.0042403"/>
      <inertia ixx="6.9397E-07" ixy="-6.0276E-12" ixz="-3.3971E-12" iyy="2.3039E-07" iyz="-9.1777E-08" izz="6.4339E-07"/>
    </inertial>
    <visual>
      <origin rpy="0 0 0" xyz="0 0 0"/>
      <geometry>
        <mesh filename="package://inspire_hand_r/meshes/R_middle_proximal.STL"/>
      </geometry>
      <material name="">
        <color rgba="1 1 1 1"/>
      </material>
    </visual>
    <collision>
      <origin rpy="0 0 0" xyz="0 0 0"/>
      <geometry>
        <mesh filename="package://inspire_hand_r/meshes/R_middle_proximal.STL"/>
      </geometry>
    </collision>
  </link>
  <joint name="R_middle_MCP_joint" type="revolute">
    <origin rpy="1.3208 0 3.1416" xyz="-0.077068 -0.24897 0.054042"/>
    <parent link="R_hand_base_link"/>
    <child link="R_middle_proximal"/>
    <axis xyz="1 0 0"/>
    <limit effort="50" lower="0" upper="1.7" velocity="1"/>
  </joint>
  <link name="R_middle_distal">
    <inertial>
      <origin rpy="0 0 0" xyz="0.0063978 0.020807 0.0018039"/>
      <mass value="0.0050396"/>
      <inertia ixx="9.8384E-07" ixy="5.3828E-12" ixz="3.4908E-12" iyy="1.7328E-07" iyz="-2.5594E-07" izz="8.914E-07"/>
    </inertial>
    <visual>
      <origin rpy="0 0 0" xyz="0 0 0"/>
      <geometry>
        <mesh filename="package://inspire_hand_r/meshes/R_middle_distal.STL"/>
      </geometry>
      <material name="">
        <color rgba="1 1 1 1"/>
      </material>
    </visual>
    <collision>
      <origin rpy="0 0 0" xyz="0 0 0"/>
      <geometry>
        <mesh filename="package://inspire_hand_r/meshes/R_middle_distal.STL"/>
      </geometry>
    </collision>
  </link>
  <joint name="R_middle_DIP_joint" type="revolute">
    <origin rpy="0.071413 0 0" xyz="0.0016673 0.030445 0.010275"/>
    <parent link="R_middle_proximal"/>
    <child link="R_middle_distal"/>
    <axis xyz="1 0 0"/>
    <limit effort="50" lower="0" upper="1.6" velocity="1"/>
  </joint>
  <link name="R_ring_proximal">
    <inertial>
      <origin rpy="0 0 0" xyz="0.0080207 0.011884 0.0016959"/>
      <mass value="0.0042403"/>
      <inertia ixx="6.9397E-07" ixy="-6.088E-12" ixz="-3.1846E-12" iyy="2.3039E-07" iyz="-9.1776E-08" izz="6.4339E-07"/>
    </inertial>
    <visual>
      <origin rpy="0 0 0" xyz="0 0 0"/>
      <geometry>
        <mesh filename="package://inspire_hand_r/meshes/R_ring_proximal.STL"/>
      </geometry>
      <material name="">
        <color rgba="1 1 1 1"/>
      </material>
    </visual>
    <collision>
      <origin rpy="0 0 0" xyz="0 0 0"/>
      <geometry>
        <mesh filename="package://inspire_hand_r/meshes/R_ring_proximal.STL"/>
      </geometry>
    </collision>
  </link>
  <joint name="R_ring_MCP_joint" type="revolute">
    <origin rpy="1.3208 -0.05236 3.1416" xyz="-0.057894 -0.24897 0.053119"/>
    <parent link="R_hand_base_link"/>
    <child link="R_ring_proximal"/>
    <axis xyz="1 0 0"/>
    <limit effort="50" lower="0" upper="1.7" velocity="1"/>
  </joint>
  <link name="R_ring_distal">
    <inertial>
      <origin rpy="0 0 0" xyz="0.0080209 0.019591 0.0019565"/>
      <mass value="0.0045683"/>
      <inertia ixx="7.8177E-07" ixy="4.448E-13" ixz="7.2441E-13" iyy="1.5635E-07" iyz="-2.1007E-07" izz="7.0082E-07"/>
    </inertial>
    <visual>
      <origin rpy="0 0 0" xyz="0 0 0"/>
      <geometry>
        <mesh filename="package://inspire_hand_r/meshes/R_ring_distal.STL"/>
      </geometry>
      <material name="">
        <color rgba="1 1 1 1"/>
      </material>
    </visual>
    <collision>
      <origin rpy="0 0 0" xyz="0 0 0"/>
      <geometry>
        <mesh filename="package://inspire_hand_r/meshes/R_ring_distal.STL"/>
      </geometry>
    </collision>
  </link>
  <joint name="R_ring_DIP_joint" type="revolute">
    <origin rpy="0.039748 0 0" xyz="0 0.030445 0.010275"/>
    <parent link="R_ring_proximal"/>
    <child link="R_ring_distal"/>
    <axis xyz="1 0 0"/>
    <limit effort="50" lower="0" upper="1.6" velocity="1"/>
  </joint>
  <link name="R_pinky_proximal">
    <inertial>
      <origin rpy="0 0 0" xyz="0.0078887 0.011884 0.0016959"/>
      <mass value="0.0042403"/>
      <inertia ixx="6.9397E-07" ixy="-6.2993E-12" ixz="-3.3535E-12" iyy="2.3039E-07" iyz="-9.1776E-08" izz="6.4339E-07"/>
    </inertial>
    <visual>
      <origin rpy="0 0 0" xyz="0 0 0"/>
      <geometry>
        <mesh filename="package://inspire_hand_r/meshes/R_pinky_proximal.STL"/>
      </geometry>
      <material name="">
        <color rgba="1 1 1 1"/>
      </material>
    </visual>
    <collision>
      <origin rpy="0 0 0" xyz="0 0 0"/>
      <geometry>
        <mesh filename="package://inspire_hand_r/meshes/R_pinky_proximal.STL"/>
      </geometry>
    </collision>
  </link>
  <joint name="R_pinky_MCP_joint" type="revolute">
    <origin rpy="1.3208 -0.10472 -3.1416" xyz="-0.038882 -0.24897 0.051205"/>
    <parent link="R_hand_base_link"/>
    <child link="R_pinky_proximal"/>
    <axis xyz="1 0 0"/>
    <limit effort="50" lower="0" upper="1.7" velocity="1"/>
  </joint>
  <link name="R_pinky_distal">
    <inertial>
      <origin rpy="0 0 0" xyz="0.0078857 0.016239 0.0022243"/>
      <mass value="0.0035996"/>
      <inertia ixx="4.4867E-07" ixy="6.675E-11" ixz="-1.9009E-11" iyy="1.2248E-07" iyz="-1.3511E-07" izz="3.8689E-07"/>
    </inertial>
    <visual>
      <origin rpy="0 0 0" xyz="0 0 0"/>
      <geometry>
        <mesh filename="package://inspire_hand_r/meshes/R_pinky_distal.STL"/>
      </geometry>
      <material name="">
        <color rgba="1 1 1 1"/>
      </material>
    </visual>
    <collision>
      <origin rpy="0 0 0" xyz="0 0 0"/>
      <geometry>
        <mesh filename="package://inspire_hand_r/meshes/R_pinky_distal.STL"/>
      </geometry>
    </collision>
  </link>
  <joint name="R_pinky_DIP_joint" type="revolute">
    <origin rpy="-0.037691 0 0" xyz="0 0.030445 0.010275"/>
    <parent link="R_pinky_proximal"/>
    <child link="R_pinky_distal"/>
    <axis xyz="1 0 0"/>
    <limit effort="50" lower="0" upper="1.6" velocity="1"/>
  </joint>
  <joint name="right_hand_base_joint" type="fixed">
    <origin rpy="0 0 0" xyz="0.0783 0.2488 0.08306"/>
    <parent link="rb1_right_arm_tool0"/>
    <child link="R_hand_base_link"/>
  </joint>

  <link name="L_hand_base_link">
    <inertial>
      <origin rpy="0 0 0" xyz="-0.076247 -0.1691 0.24613"/>
      <mass value="0.14143"/>
      <inertia ixx="7.7231E-05" ixy="-1.5968E-06" ixz="1.7694E-06" iyy="8.3835E-05" iyz="2.1995E-06" izz="0.0001234"/>
    </inertial>
    <visual>
      <origin rpy="0 0 0" xyz="0 0 0"/>
      <geometry>
        <mesh filename="package://inspire_hand_l/meshes/L_hand_base_link.STL"/>
      </geometry>
      <material name="">
        <color rgba="1 1 1 1"/>
      </material>
    </visual>
    <collision>
      <origin rpy="0 0 0" xyz="0 0 0"/>
      <geometry>
        <mesh filename="package://inspire_hand_l/meshes/L_hand_base_link.STL"/>
      </geometry>
    </collision>
  </link>
  <link name="L_thumb_proximal_base">
    <inertial>
      <origin rpy="0 0 0" xyz="-0.0048772 0.00668 -0.00044071"/>
      <mass value="0.0018869"/>
      <inertia ixx="5.2003E-08" ixy="4.8353E-09" ixz="6.6444E-09" iyy="6.7434E-08" iyz="-5.4476E-10" izz="8.5319E-08"/>
    </inertial>
    <visual>
      <origin rpy="0 0 0" xyz="0 0 0"/>
      <geometry>
        <mesh filename="package://inspire_hand_l/meshes/L_thumb_proximal_base.STL"/>
      </geometry>
      <material name="">
        <color rgba="1 1 1 1"/>
      </material>
    </visual>
    <collision>
      <origin rpy="0 0 0" xyz="0 0 0"/>
      <geometry>
        <mesh filename="package://inspire_hand_l/meshes/L_thumb_proximal_base.STL"/>
      </geometry>
    </collision>
  </link>
  <joint name="L_thumb_MCP_joint1" type="revolute">
    <origin rpy="-1.5708 0 -0.16939" xyz="-0.098633 -0.23173 -0.15826"/>
    <parent link="L_hand_base_link"/>
    <child link="L_thumb_proximal_base"/>
    <axis xyz="0 1 0"/>
    <limit effort="50" lower="0.3" upper="1.4" velocity="1"/>
  </joint>
  <link name="L_thumb_proximal">
    <inertial>
      <origin rpy="0 0 0" xyz="-3.8578E-05 0.025335 0.0016982"/>
      <mass value="0.0066101"/>
      <inertia ixx="2.787E-06" ixy="1.3042E-10" ixz="1.3413E-09" iyy="8.9435E-07" iyz="2.1426E-07" izz="2.4105E-06"/>
    </inertial>
    <visual>
      <origin rpy="0 0 0" xyz="0 0 0"/>
      <geometry>
        <mesh filename="package://inspire_hand_l/meshes/L_thumb_proximal.STL"/>
      </geometry>
      <material name="">
        <color rgba="1 1 1 1"/>
      </material>
    </visual>
    <collision>
      <origin rpy="0 0 0" xyz="0 0 0"/>
      <geometry>
        <mesh filename="package://inspire_hand_l/meshes/L_thumb_proximal.STL"/>
      </geometry>
    </collision>
  </link>
  <joint name="L_thumb_MCP_joint2" type="revolute">
    <origin rpy="2.1656 -1.5708 0" xyz="-0.0115 0.005 0"/>
    <parent link="L_thumb_proximal_base"/>
    <child link="L_thumb_proximal"/>
    <axis xyz="-1 0 0"/>
    <limit effort="50" lower="1.5" upper="2" velocity="1"/>
  </joint>
  <link name="L_thumb_intermediate">
    <inertial>
      <origin rpy="0 0 0" xyz="-1.7401E-07 0.0072516 0.0064286"/>
      <mass value="0.0037844"/>
      <inertia ixx="4.6532E-07" ixy="-9.1152E-13" ixz="-3.8682E-12" iyy="2.6856E-07" iyz="6.4144E-08" izz="4.252E-07"/>
    </inertial>
    <visual>
      <origin rpy="0 0 0" xyz="0 0 0"/>
      <geometry>
        <mesh filename="package://inspire_hand_l/meshes/L_thumb_intermediate.STL"/>
      </geometry>
      <material name="">
        <color rgba="1 1 1 1"/>
      </material>
    </visual>
    <collision>
      <origin rpy="0 0 0" xyz="0 0 0"/>
      <geometry>
        <mesh filename="package://inspire_hand_l/meshes/L_thumb_intermediate.STL"/>
      </geometry>
    </collision>
  </link>
  <joint name="L_thumb_PIP_joint" type="revolute">
    <origin rpy="0.038299 0 0" xyz="0 0.055863 -0.0039241"/>
    <parent link="L_thumb_proximal"/>
    <child link="L_thumb_intermediate"/>
    <axis xyz="-1 0 0"/>
    <limit effort="50" lower="0" upper="1" velocity="1"/>
  </joint>
  <link name="L_thumb_distal">
    <inertial>
      <origin rpy="0 0 0" xyz="-3.3076E-06 0.010511 0.00057861"/>
      <mass value="0.003344"/>
      <inertia ixx="2.0026E-07" ixy="-1.4157E-10" ixz="5.6213E-11" iyy="8.7108E-08" iyz="2.4414E-08" izz="1.8974E-07"/>
    </inertial>
    <visual>
      <origin rpy="0 0 0" xyz="0 0 0"/>
      <geometry>
        <mesh filename="package://inspire_hand_l/meshes/L_thumb_distal.STL"/>
      </geometry>
      <material name="">
        <color rgba="1 1 1 1"/>
      </material>
    </visual>
    <collision>
      <origin rpy="0 0 0" xyz="0 0 0"/>
      <geometry>
        <mesh filename="package://inspire_hand_l/meshes/L_thumb_distal.STL"/>
      </geometry>
    </collision>
  </link>
  <joint name="L_thumb_DIP_joint" type="revolute">
    <origin rpy="0.011642 0 0" xyz="0 0.022558 0.0020717"/>
    <parent link="L_thumb_intermediate"/>
    <child link="L_thumb_distal"/>
    <axis xyz="-1 0 0"/>
    <limit effort="50" lower="0" upper="1.2" velocity="1"/>
  </joint>
  <link name="L_index_proximal">
    <inertial>
      <origin rpy="0 0 0" xyz="0.0080456 0.011884 -0.0016957"/>
      <mass value="0.0042405"/>
      <inertia ixx="6.9402E-07" ixy="1.4654E-11" ixz="-2.3231E-12" iyy="2.3041E-07" iyz="9.1802E-08" izz="6.4342E-07"/>
    </inertial>
    <visual>
      <origin rpy="0 0 0" xyz="0 0 0"/>
      <geometry>
        <mesh filename="package://inspire_hand_l/meshes/L_index_proximal.STL"/>
      </geometry>
      <material name="">
        <color rgba="1 1 1 1"/>
      </material>
    </visual>
    <collision>
      <origin rpy="0 0 0" xyz="0 0 0"/>
      <geometry>
        <mesh filename="package://inspire_hand_l/meshes/L_index_proximal.STL"/>
      </geometry>
    </collision>
  </link>
  <joint name="L_index_MCP_joint" type="revolute">
    <origin rpy="-1.3208 -0.034907 3.1416" xyz="-0.096414 -0.24897 -0.24007"/>
    <parent link="L_hand_base_link"/>
    <child link="L_index_proximal"/>
    <axis xyz="-1 0 0"/>
    <limit effort="50" lower="0" upper="1.7" velocity="1"/>
  </joint>
  <link name="L_index_distal">
    <inertial>
      <origin rpy="0 0 0" xyz="0.0063917 0.01959 -0.0019564"/>
      <mass value="0.0045682"/>
      <inertia ixx="7.8176E-07" ixy="-7.7162E-14" ixz="3.9272E-13" iyy="1.5634E-07" iyz="2.1006E-07" izz="7.0081E-07"/>
    </inertial>
    <visual>
      <origin rpy="0 0 0" xyz="0 0 0"/>
      <geometry>
        <mesh filename="package://inspire_hand_l/meshes/L_index_distal.STL"/>
      </geometry>
      <material name="">
        <color rgba="1 1 1 1"/>
      </material>
    </visual>
    <collision>
      <origin rpy="0 0 0" xyz="0 0 0"/>
      <geometry>
        <mesh filename="package://inspire_hand_l/meshes/L_index_distal.STL"/>
      </geometry>
    </collision>
  </link>
  <joint name="L_index_DIP_joint" type="revolute">
    <origin rpy="-0.039748 0 0" xyz="0.0016538 0.030445 -0.010275"/>
    <parent link="L_index_proximal"/>
    <child link="L_index_distal"/>
    <axis xyz="-1 0 0"/>
    <limit effort="50" lower="0" upper="1.6" velocity="1"/>
  </joint>
  <link name="L_middle_proximal">
    <inertial>
      <origin rpy="0 0 0" xyz="0.0080653 0.011884 -0.0016957"/>
      <mass value="0.0042405"/>
      <inertia ixx="6.9402E-07" ixy="1.4338E-11" ixz="-2.3917E-12" iyy="2.3041E-07" iyz="9.1802E-08" izz="6.4342E-07"/>
    </inertial>
    <visual>
      <origin rpy="0 0 0" xyz="0 0 0"/>
      <geometry>
        <mesh filename="package://inspire_hand_l/meshes/L_middle_proximal.STL"/>
      </geometry>
      <material name="">
        <color rgba="1 1 1 1"/>
      </material>
    </visual>
    <collision>
      <origin rpy="0 0 0" xyz="0 0 0"/>
      <geometry>
        <mesh filename="package://inspire_hand_l/meshes/L_middle_proximal.STL"/>
      </geometry>
    </collision>
  </link>
  <joint name="L_middle_MCP_joint" type="revolute">
    <origin rpy="-1.3208 0 3.1416" xyz="-0.077068 -0.24897 -0.24016"/>
    <parent link="L_hand_base_link"/>
    <child link="L_middle_proximal"/>
    <axis xyz="-1 0 0"/>
    <limit effort="50" lower="0" upper="1.7" velocity="1"/>
  </joint>
  <link name="L_middle_distal">
    <inertial>
      <origin rpy="0 0 0" xyz="0.0063955 0.020807 -0.0018039"/>
      <mass value="0.0050397"/>
      <inertia ixx="9.8385E-07" ixy="-4.0683E-12" ixz="-1.7233E-12" iyy="1.7328E-07" iyz="2.5594E-07" izz="8.9141E-07"/>
    </inertial>
    <visual>
      <origin rpy="0 0 0" xyz="0 0 0"/>
      <geometry>
        <mesh filename="package://inspire_hand_l/meshes/L_middle_distal.STL"/>
      </geometry>
      <material name="">
        <color rgba="1 1 1 1"/>
      </material>
    </visual>
    <collision>
      <origin rpy="0 0 0" xyz="0 0 0"/>
      <geometry>
        <mesh filename="package://inspire_hand_l/meshes/L_middle_distal.STL"/>
      </geometry>
    </collision>
  </link>
  <joint name="L_middle_DIP_joint" type="revolute">
    <origin rpy="-0.071413 0 0" xyz="0.0016698 0.030445 -0.010275"/>
    <parent link="L_middle_proximal"/>
    <child link="L_middle_distal"/>
    <axis xyz="-1 0 0"/>
    <limit effort="50" lower="0" upper="1.6" velocity="1"/>
  </joint>
  <link name="L_ring_proximal">
    <inertial>
      <origin rpy="0 0 0" xyz="0.010821 0.011884 -0.0016957"/>
      <mass value="0.0042405"/>
      <inertia ixx="6.9402E-07" ixy="1.3923E-11" ixz="-2.5637E-12" iyy="2.3041E-07" iyz="9.1802E-08" izz="6.4342E-07"/>
    </inertial>
    <visual>
      <origin rpy="0 0 0" xyz="0 0 0"/>
      <geometry>
        <mesh filename="package://inspire_hand_l/meshes/L_ring_proximal.STL"/>
      </geometry>
      <material name="">
        <color rgba="1 1 1 1"/>
      </material>
    </visual>
    <collision>
      <origin rpy="0 0 0" xyz="0 0 0"/>
      <geometry>
        <mesh filename="package://inspire_hand_l/meshes/L_ring_proximal.STL"/>
      </geometry>
    </collision>
  </link>
  <joint name="L_ring_MCP_joint" type="revolute">
    <origin rpy="-1.3208 0.05236 3.1416" xyz="-0.055098 -0.24897 -0.23909"/>
    <parent link="L_hand_base_link"/>
    <child link="L_ring_proximal"/>
    <axis xyz="-1 0 0"/>
    <limit effort="50" lower="0" upper="1.7" velocity="1"/>
  </joint>
  <link name="L_ring_distal">
    <inertial>
      <origin rpy="0 0 0" xyz="0.009285 0.019591 -0.0019565"/>
      <mass value="0.0045682"/>
      <inertia ixx="7.8176E-07" ixy="4.4486E-13" ixz="-6.071E-14" iyy="1.5634E-07" iyz="2.1006E-07" izz="7.0081E-07"/>
    </inertial>
    <visual>
      <origin rpy="0 0 0" xyz="0 0 0"/>
      <geometry>
        <mesh filename="package://inspire_hand_l/meshes/L_ring_distal.STL"/>
      </geometry>
      <material name="">
        <color rgba="1 1 1 1"/>
      </material>
    </visual>
    <collision>
      <origin rpy="0 0 0" xyz="0 0 0"/>
      <geometry>
        <mesh filename="package://inspire_hand_l/meshes/L_ring_distal.STL"/>
      </geometry>
    </collision>
  </link>
  <joint name="L_ring_DIP_joint" type="revolute">
    <origin rpy="-0.039748 0 0" xyz="0.0015355 0.030445 -0.010275"/>
    <parent link="L_ring_proximal"/>
    <child link="L_ring_distal"/>
    <axis xyz="-1 0 0"/>
    <limit effort="50" lower="0" upper="1.6" velocity="1"/>
  </joint>
  <link name="L_pinky_proximal">
    <inertial>
      <origin rpy="0 0 0" xyz="0.013546 0.011884 -0.0016957"/>
      <mass value="0.0042405"/>
      <inertia ixx="6.9402E-07" ixy="1.4088E-11" ixz="-2.5363E-12" iyy="2.3041E-07" iyz="9.1802E-08" izz="6.4342E-07"/>
    </inertial>
    <visual>
      <origin rpy="0 0 0" xyz="0 0 0"/>
      <geometry>
        <mesh filename="package://inspire_hand_l/meshes/L_pinky_proximal.STL"/>
      </geometry>
      <material name="">
        <color rgba="1 1 1 1"/>
      </material>
    </visual>
    <collision>
      <origin rpy="0 0 0" xyz="0 0 0"/>
      <geometry>
        <mesh filename="package://inspire_hand_l/meshes/L_pinky_proximal.STL"/>
      </geometry>
    </collision>
  </link>
  <joint name="L_pinky_MCP_joint" type="revolute">
    <origin rpy="-1.3208 0.10472 3.1416" xyz="-0.033256 -0.24897 -0.23673"/>
    <parent link="L_hand_base_link"/>
    <child link="L_pinky_proximal"/>
    <axis xyz="-1 0 0"/>
    <limit effort="50" lower="0" upper="1.7" velocity="1"/>
  </joint>
  <link name="L_pinky_distal">
    <inertial>
      <origin rpy="0 0 0" xyz="0.013546 0.016245 -0.0022219"/>
      <mass value="0.0036036"/>
      <inertia ixx="4.4881E-07" ixy="-2.6544E-12" ixz="2.0643E-12" iyy="1.2252E-07" iyz="1.3507E-07" izz="3.8703E-07"/>
    </inertial>
    <visual>
      <origin rpy="0 0 0" xyz="0 0 0"/>
      <geometry>
        <mesh filename="package://inspire_hand_l/meshes/L_pinky_distal.STL"/>
      </geometry>
      <material name="">
        <color rgba="1 1 1 1"/>
      </material>
    </visual>
    <collision>
      <origin rpy="0 0 0" xyz="0 0 0"/>
      <geometry>
        <mesh filename="package://inspire_hand_l/meshes/L_pinky_distal.STL"/>
      </geometry>
    </collision>
  </link>
  <joint name="L_pinky_DIP_joint" type="revolute">
    <origin rpy="0.037691 0 0" xyz="0 0.030445 -0.010275"/>
    <parent link="L_pinky_proximal"/>
    <child link="L_pinky_distal"/>
    <axis xyz="-1 0 0"/>
    <limit effort="50" lower="0" upper="1.6" velocity="1"/>
  </joint>
  <joint name="left_hand_base_joint" type="fixed">
    
    <origin rpy="3.141592653589793 0 3.141592653589793" xyz="-0.0783 0.2488 -0.10305"/>
    <parent link="rb1_left_arm_tool0"/>
    <child link="L_hand_base_link"/>
  </joint>
  <Fin Parte Manos /-->

</robot>

